Workbook
Name V3_Trend_Months: 整体月度总销量环比走势图!$A$5:INDEX(整体月度总销量环比走势图!$A$5:$A$102,COUNTA('Data Export'!$G$1:$CZ$1))
Name V3_Trend_Sales: 整体月度总销量环比走势图!$B$5:INDEX(整体月度总销量环比走势图!$B$5:$B$102,COUNTA('Data Export'!$G$1:$CZ$1))
Name V4_CN_Brand_Names: 中国品牌市占率!$B$7:INDEX(中国品牌市占率!$B$7:$B$201,COUNTIF(中国品牌市占率!$C$7:$C$201,">0"))
Name V4_CN_Brand_Sales: 中国品牌市占率!$C$7:INDEX(中国品牌市占率!$C$7:$C$201,COUNTIF(中国品牌市占率!$C$7:$C$201,">0"))

Sheet Sheet1
A1: 品牌 | B1: AION
A2: 2 | B2: 2
A3: Row Labels | B3: 求和项:求和 | C3: 求和项:2025 十二月 | D3: 求和项:2026 一月 | E3: 求和项:2026 二月 | F3: 求和项:2026 三月 | G3: 求和项:2026 四月 | H3: 求和项:2026 五月 | I3: 求和项:2026 六月 | J3: 求和项:2026 七月
A4: ZS | B4: 0 | C4: 84 | D4: 145 | E4: 34 | F4: 41 | G4: 28 | H4: 34 | I4: 42 | J4: 44
A5: Z4 | B5: 0 | C5: 2 | D5: 2 | E5: 3 | F5: 5 | G5: 3 | H5: 8 | I5: 5 | J5: 1
A6: YUKON | B6: 0 | C6: 0 | D6: 0 | E6: 0 | F6: 0 | G6: 0 | H6: 0 | I6: 1 | J6: 0
A7: YARIS CROSS | B7: 0 | C7: 1902 | D7: 3963 | E7: 3095 | F7: 3568 | G7: 2928 | H7: 3139 | I7: 3132 | J7: 2671
A8: YARIS ATIV | B8: 0 | C8: 3530 | D8: 7283 | E8: 6051 | F8: 6405 | G8: 5430 | H8: 5716 | I8: 5994 | J8: 5691
A9: YARIS | B9: 0 | C9: 291 | D9: 362 | E9: 314 | F9: 423 | G9: 348 | H9: 317 | I9: 350 | J9: 332
A10: Y PLUS | B10: 0 | C10: 122 | D10: 1791 | E10: 8 | F10: 18 | G10: 29 | H10: 140 | I10: 103 | J10: 112
A11: XV | B11: 0 | C11: 7 | D11: 34 | E11: 20 | F11: 17 | G11: 6 | H11: 5 | I11: 3 | J11: 0
A12: X-TRAIL | B12: 0 | C12: 4 | D12: 25 | E12: 33 | F12: 41 | G12: 48 | H12: 31 | I12: 35 | J12: 23
A13: XPANDER | B13: 0 | C13: 288 | D13: 463 | E13: 469 | F13: 512 | G13: 438 | H13: 575 | I13: 386 | J13: 372
A14: XM | B14: 0 | C14: 1 | D14: 3 | E14: 7 | F14: 9 | G14: 9 | H14: 3 | I14: 3 | J14: 7
A15: XL7 | B15: 0 | C15: 12 | D15: 11 | E15: 17 | F15: 19 | G15: 15 | H15: 10 | I15: 13 | J15: 12
... A421: Grand Total | B421: 0 | C421: 42729 | D421: 92621 | E421: 49037 | F421: 59840 | G421: 49245 | H421: 61880 | I421: 62489 | J421: 58738

Sheet Data Export
A1: 车辆/销量类型 | B1: 国家 | C1: 品牌 | D1: 车型 | E1: 车款名称 | F1: 车身形式 | G1: 2025 十二月 | H1: 2026 一月 | I1: 2026 二月 | J1: 2026 三月 | K1: 2026 四月 | L1: 2026 五月 | M1: 2026 六月 | N1: 2026 七月
A2: 乘用车 注册数据 | B2: 泰国 | C2: AION | D2: ES | E2: BEV 55KWH AUTO | F2: 三厢轿车 | G2: 43 | H2: 406 | I2: 0 | J2: 0 | K2: 0 | L2: 82 | M2: 89 | N2: 15
A3: 乘用车 注册数据 | B3: 泰国 | C3: AION | D3: UT | E3: BEV 50KWH 420 STANDARD AUTO | F3: 掀背轿车 | G3: 755 | H3: 810 | I3: 239 | J3: 554 | K3: 393 | L3: 530 | M3: 568 | N3: 708
A4: 乘用车 注册数据 | B4: 泰国 | C4: AION | D4: UT | E4: BEV 60KWH 500 PREMIUM AUTO | F4: 掀背轿车 | G4: 325 | H4: 709 | I4: 54 | J4: 65 | K4: 88 | L4: 188 | M4: 224 | N4: 338
A5: 乘用车 注册数据 | B5: 泰国 | C5: AION | D5: V | E5: BEV 65KWH 500 PREMIUM AUTO | F5: 运动型多功能车 | G5: 0 | H5: 12 | I5: 1 | J5: 1 | K5: 0 | L5: 123 | M5: 430 | N5: 346
A6: 乘用车 注册数据 | B6: 泰国 | C6: AION | D6: V | E6: BEV 75KWH 602 LUXURY AUTO | F6: 运动型多功能车 | G6: 290 | H6: 1255 | I6: 47 | J6: 337 | K6: 294 | L6: 549 | M6: 459 | N6: 208
A7: 乘用车 注册数据 | B7: 泰国 | C7: AION | D7: Y PLUS | E7: 453 | F7: 运动型多功能车 | G7: 63 | H7: 956 | I7: 7 | J7: 14 | K7: 23 | L7: 35 | M7: 10 | N7: 12
A8: 乘用车 注册数据 | B8: 泰国 | C8: AION | D8: Y PLUS | E8: BEV 51KWH 410 PREMIUM AUTO | F8: 运动型多功能车 | G8: 0 | H8: 0 | I8: 0 | J8: 0 | K8: 0 | L8: 80 | M8: 41 | N8: 93
A9: 乘用车 注册数据 | B9: 泰国 | C9: AION | D9: Y PLUS | E9: BEV 63KWH 490 PREMIUM AUTO | F9: 运动型多功能车 | G9: 59 | H9: 835 | I9: 1 | J9: 4 | K9: 6 | L9: 25 | M9: 52 | N9: 7
A10: 乘用车 注册数据 | B10: 泰国 | C10: ASTON MARTIN | D10: DB11 | E10: V8 | F10: 硬顶跑车 | G10: 0 | H10: 0 | I10: 0 | J10: 0 | K10: 0 | L10: 0 | M10: 1 | N10: 0
A11: 乘用车 注册数据 | B11: 泰国 | C11: ASTON MARTIN | D11: DB12 | E11: 4.0 V8 AUTO | F11: 硬顶跑车 | G11: 0 | H11: 0 | I11: 1 | J11: 1 | K11: 0 | L11: 0 | M11: 0 | N11: 1
A12: 乘用车 注册数据 | B12: 泰国 | C12: ASTON MARTIN | D12: DBX | E12: 4.0 V8 707 AUTO 4WD | F12: 运动型多功能车 | G12: 0 | H12: 0 | I12: 0 | J12: 0 | K12: 2 | L12: 0 | M12: 1 | N12: 0
A13: 乘用车 注册数据 | B13: 泰国 | C13: ASTON MARTIN | D13: RAPIDE | E13: S | F13: 掀背轿车 | G13: 1 | H13: 0 | I13: 0 | J13: 0 | K13: 0 | L13: 0 | M13: 0 | N13: 0
... A301: 乘用车 注册数据 | B301: 泰国 | C301: HONDA | D301: MOBILIO | E301: 453 | F301: 小型MPV | G301: 0 | H301: 1 | I301: 0 | J301: 0 | K301: 0 | L301: 0 | M301: 0 | N301: 0
A302: 乘用车 注册数据 | B302: 泰国 | C302: HONDA | D302: MOBILIO | E302: 1.5 | F302: 小型MPV | G302: 0 | H302: 0 | I302: 0 | J302: 0 | K302: 1 | L302: 0 | M302: 0 | N302: 0
A303: 乘用车 注册数据 | B303: 泰国 | C303: HONDA | D303: N-BOX | E303: CUSTOM TURBO | F303: ? | G303: 0 | H303: 0 | I303: 0 | J303: 0 | K303: 0 | L303: 0 | M303: 0 | N303: 1
A304: 乘用车 注册数据 | B304: 泰国 | C304: HONDA | D304: N-BOX | E304: JOY TURBO | F304: ? | G304: 0 | H304: 0 | I304: 0 | J304: 1 | K304: 0 | L304: 0 | M304: 1 | N304: 0
A305: 乘用车 注册数据 | B305: 泰国 | C305: HONDA | D305: ODYSSEY | E305: HEV ABSOLUTE EX | F305: 小型厢式车 | G305: 0 | H305: 1 | I305: 0 | J305: 4 | K305: 0 | L305: 1 | M305: 0 | N305: 1
A306: 乘用车 注册数据 | B306: 泰国 | C306: HONDA | D306: OTHER | E306: 453 | F306: ? | G306: 0 | H306: 1 | I306: 0 | J306: 0 | K306: 0 | L306: 0 | M306: 0 | N306: 0
A307: 乘用车 注册数据 | B307: 泰国 | C307: HONDA | D307: OTHER | E307: WAVE125 | F307: ? | G307: 0 | H307: 0 | I307: 0 | J307: 0 | K307: 0 | L307: 0 | M307: 1 | N307: 0
A308: 乘用车 注册数据 | B308: 泰国 | C308: HONDA | D308: PRELUDE | E308: E:HEV | F308: 硬顶跑车 | G308: 0 | H308: 0 | I308: 1 | J308: 2 | K308: 0 | L308: 1 | M308: 0 | N308: 1
A309: 乘用车 注册数据 | B309: 泰国 | C309: HONDA | D309: S660 | E309: 453 | F309: ? | G309: 0 | H309: 0 | I309: 0 | J309: 0 | K309: 0 | L309: 0 | M309: 1 | N309: 0
A310: 乘用车 注册数据 | B310: 泰国 | C310: HONDA | D310: S660 | E310: MODULO X SPECIAL VER.Z | F310: ? | G310: 0 | H310: 0 | I310: 1 | J310: 0 | K310: 0 | L310: 0 | M310: 0 | N310: 0
A311: 乘用车 注册数据 | B311: 泰国 | C311: HONDA | D311: S660 | E311: SPOON | F311: ? | G311: 0 | H311: 0 | I311: 0 | J311: 1 | K311: 0 | L311: 0 | M311: 0 | N311: 0
A312: 乘用车 注册数据 | B312: 泰国 | C312: HONDA | D312: STEP WGN | E312: E:HEV SPADA PREMIUM | F312: 小型厢式车 | G312: 0 | H312: 0 | I312: 0 | J312: 1 | K312: 1 | L312: 0 | M312: 0 | N312: 0
A313: 乘用车 注册数据 | B313: 泰国 | C313: HONDA | D313: STEP WGN | E313: 2.0 E:HEV SPADA E-CVT | F313: 小型厢式车 | G313: 0 | H313: 14 | I313: 13 | J313: 41 | K313: 57 | L313: 56 | M313: 82 | N313: 70
A314: 乘用车 注册数据 | B314: 泰国 | C314: HONDA | D314: STEP WGN | E314: E:HEV AIR | F314: 小型厢式车 | G314: 1 | H314: 0 | I314: 0 | J314: 0 | K314: 0 | L314: 0 | M314: 0 | N314: 0
... A371: 乘用车 注册数据 | B371: 泰国 | C371: LAMBORGHINI | D371: URUS | E371: 4.0 V8 S | F371: 运动型多功能车 | G371: 0 | H371: 0 | I371: 0 | J371: 1 | K371: 1 | L371: 0 | M371: 0 | N371: 0
A372: 乘用车 注册数据 | B372: 泰国 | C372: LAND ROVER | D372: DEFENDER | E372: 2 | F372: 运动型多功能车 | G372: 0 | H372: 0 | I372: 0 | J372: 0 | K372: 1 | L372: 0 | M372: 0 | N372: 0
A373: 乘用车 注册数据 | B373: 泰国 | C373: LAND ROVER | D373: DEFENDER | E373: 2.0 P400E X-DYNAMIC SE PLUS 110 AUTO 4WD | F373: 运动型多功能车 | G373: 5 | H373: 0 | I373: 0 | J373: 0 | K373: 0 | L373: 0 | M373: 0 | N373: 0
A374: 乘用车 注册数据 | B374: 泰国 | C374: LAND ROVER | D374: DEFENDER | E374: 2.0PHEV | F374: 运动型多功能车 | G374: 0 | H374: 2 | I374: 0 | J374: 1 | K374: 0 | L374: 1 | M374: 1 | N374: 3
A375: 乘用车 注册数据 | B375: 泰国 | C375: LAND ROVER | D375: DEFENDER | E375: 3 | F375: 运动型多功能车 | G375: 1 | H375: 0 | I375: 0 | J375: 0 | K375: 0 | L375: 0 | M375: 0 | N375: 0
A376: 乘用车 注册数据 | B376: 泰国 | C376: LAND ROVER | D376: DEFENDER | E376: 3.0 D250 X-DNM SE PLUS | F376: 运动型多功能车 | G376: 0 | H376: 0 | I376: 0 | J376: 0 | K376: 0 | L376: 0 | M376: 1 | N376: 0
A377: 乘用车 注册数据 | B377: 泰国 | C377: LAND ROVER | D377: DEFENDER | E377: 3.0 MHEV | F377: 运动型多功能车 | G377: 0 | H377: 2 | I377: 2 | J377: 0 | K377: 0 | L377: 0 | M377: 1 | N377: 0
A378: 乘用车 注册数据 | B378: 泰国 | C378: LAND ROVER | D378: DEFENDER | E378: 5.0 P425 X 110 | F378: 运动型多功能车 | G378: 0 | H378: 0 | I378: 1 | J378: 0 | K378: 0 | L378: 0 | M378: 0 | N378: 0
A379: 乘用车 注册数据 | B379: 泰国 | C379: LAND ROVER | D379: DISCOVERY | E379: 3.0 MHEV | F379: 运动型多功能车 | G379: 0 | H379: 0 | I379: 0 | J379: 0 | K379: 0 | L379: 0 | M379: 1 | N379: 0
A380: 乘用车 注册数据 | B380: 泰国 | C380: LAND ROVER | D380: RANGE ROVER | E380: 3 | F380: 运动型多功能车 | G380: 2 | H380: 4 | I380: 2 | J380: 4 | K380: 1 | L380: 2 | M380: 1 | N380: 3
A381: 乘用车 注册数据 | B381: 泰国 | C381: LAND ROVER | D381: RANGE ROVER | E381: 3.0 4WD | F381: 运动型多功能车 | G381: 0 | H381: 0 | I381: 0 | J381: 1 | K381: 0 | L381: 0 | M381: 0 | N381: 0
A382: 乘用车 注册数据 | B382: 泰国 | C382: LAND ROVER | D382: RANGE ROVER | E382: P460E PHEV | F382: 运动型多功能车 | G382: 0 | H382: 1 | I382: 0 | J382: 0 | K382: 0 | L382: 0 | M382: 0 | N382: 0
A383: 乘用车 注册数据 | B383: 泰国 | C383: LAND ROVER | D383: RANGE ROVER EVOQUE | E383: 1.5 P300E AUTOBIOGRAPHY PLUS AT 4WD | F383: 运动型多功能车 | G383: 0 | H383: 2 | I383: 1 | J383: 0 | K383: 0 | L383: 0 | M383: 0 | N383: 0
...

Sheet V1_Calc
A1: 组合键 | B1: 品牌 | C1: 车型 | D1: 最新月份销量 | E1: 整体唯一排名 | F1: 中国品牌标记 | G1: 车身大类 | H1: 原始行组合键 | I1: 原始行最新月销量 | J1: 原始行车身大类 | K1: 中国车型排名 | L1: 轿车排名 | M1: MPV排名 | N1: SUV排名 | O1: 中国轿车排名 | P1: 中国MPV排名 | Q1: 中国SUV排名 | S1: V2 计算逻辑说明
A2: =IFERROR(INDEX($H$2:$H$3000,MATCH(0,INDEX(COUNTIF($A$1:A1,$H$2:$H$3000)+($H$2:$H$3000=""),0,0),0)),"") -> AION♦ES | B2: =IF(A2="","",LEFT(A2,FIND("♦",A2)-1)) -> AION | C2: =IF(A2="","",MID(A2,FIND("♦",A2)+1,999)) -> ES | D2: =IF(A2="","",SUMIF($H$2:$H$3000,A2,$I$2:$I$3000)) -> 15 | E2: =IF(D2="","",_xlfn.RANK.EQ(D2,$D$2:$D$1001,0)+COUNTIF($D$2:D2,D2)-1) -> 127 | F2: =IF(B2="","",--(COUNTIF(CN_Brands!$A$2:$A$300,UPPER(B2))>0)) -> 1 | G2: =IF(A2="","",IFERROR(INDEX($J$2:$J$3000,MATCH(A2,$H$2:$H$3000,0)),"其他")) -> 轿车 | H2: =IF(AND('Data Export'!A2=前十整体车型排名!$B$2,'Data Export'!B2=前十整体车型排名!$B$3,'Data Export'!D2<>""),UPPER('Data Export'!C2)&"♦"&'Data Export'!D2,"") -> AION♦ES | I2: =IF(H2="","",IFERROR(INDEX('Data Export'!G2:CZ2,1,MATCH(前十整体车型排名!$B$4,'Data Export'!$G$1:$CZ$1,0)),0)) -> 15 | J2: =IF(H2="","",IF(OR('Data Export'!F2="三厢轿车",'Data Export'!F2="掀背轿车",'Data Export'!F2="旅行车",'Data Export'!F2="微型车",'Data Export'!F2="硬顶跑车",'Data Export'!F2="敞蓬车",'Data Export'!F2="Targa"),"轿车",IF(OR('Data Export'!F2="小型MPV",'Data Export'!F2="客车"),"MPV",IF('Data Export'!F2="运动型多功能车","SUV","其他")))) -> 轿车 | K2: =IF(OR(D2="",NOT(F2=1)),"",1+SUMPRODUCT(($F$2:$F$1001=1)*($D$2:$D$1001>D2))+COUNTIFS($F$2:F2,1,$D$2:D2,D2)-1) -> 51 | L2: =IF(OR(D2="",NOT(G2="轿车")),"",1+SUMPRODUCT(($G$2:$G$1001="轿车")*($D$2:$D$1001>D2))+COUNTIFS($G$2:G2,"轿车",$D$2:D2,D2)-1) -> 32 | M2: =IF(OR(D2="",NOT(G2="MPV")),"",1+SUMPRODUCT(($G$2:$G$1001="MPV")*($D$2:$D$1001>D2))+COUNTIFS($G$2:G2,"MPV",$D$2:D2,D2)-1) | N2: =IF(OR(D2="",NOT(G2="SUV")),"",1+SUMPRODUCT(($G$2:$G$1001="SUV")*($D$2:$D$1001>D2))+COUNTIFS($G$2:G2,"SUV",$D$2:D2,D2)-1) | O2: =IF(OR(D2="",NOT(AND(F2=1,G2="轿车"))),"",1+SUMPRODUCT(($F$2:$F$1001=1)*($G$2:$G$1001="轿车")*($D$2:$D$1001>D2))+COUNTIFS($F$2:F2,1,$G$2:G2,"轿车",$D$2:D2,D2)-1) -> 12 | P2: =IF(OR(D2="",NOT(AND(F2=1,G2="MPV"))),"",1+SUMPRODUCT(($F$2:$F$1001=1)*($G$2:$G$1001="MPV")*($D$2:$D$1001>D2))+COUNTIFS($F$2:F2,1,$G$2:G2,"MPV",$D$2:D2,D2)-1) | Q2: =IF(OR(D2="",NOT(AND(F2=1,G2="SUV"))),"",1+SUMPRODUCT(($F$2:$F$1001=1)*($G$2:$G$1001="SUV")*($D$2:$D$1001>D2))+COUNTIFS($F$2:F2,1,$G$2:G2,"SUV",$D$2:D2,D2)-1) | S2: 中国品牌：CN_Brands 中“自主或合资＝自主”的品牌。
A3: =IFERROR(INDEX($H$2:$H$3000,MATCH(0,INDEX(COUNTIF($A$1:A2,$H$2:$H$3000)+($H$2:$H$3000=""),0,0),0)),"") -> AION♦UT | B3: =IF(A3="","",LEFT(A3,FIND("♦",A3)-1)) -> AION | C3: =IF(A3="","",MID(A3,FIND("♦",A3)+1,999)) -> UT | D3: =IF(A3="","",SUMIF($H$2:$H$3000,A3,$I$2:$I$3000)) -> 1046 | E3: =IF(D3="","",_xlfn.RANK.EQ(D3,$D$2:$D$1001,0)+COUNTIF($D$2:D3,D3)-1) -> 10 | F3: =IF(B3="","",--(COUNTIF(CN_Brands!$A$2:$A$300,UPPER(B3))>0)) -> 1 | G3: =IF(A3="","",IFERROR(INDEX($J$2:$J$3000,MATCH(A3,$H$2:$H$3000,0)),"其他")) -> 轿车 | H3: =IF(AND('Data Export'!A3=前十整体车型排名!$B$2,'Data Export'!B3=前十整体车型排名!$B$3,'Data Export'!D3<>""),UPPER('Data Export'!C3)&"♦"&'Data Export'!D3,"") -> AION♦UT | I3: =IF(H3="","",IFERROR(INDEX('Data Export'!G3:CZ3,1,MATCH(前十整体车型排名!$B$4,'Data Export'!$G$1:$CZ$1,0)),0)) -> 708 | J3: =IF(H3="","",IF(OR('Data Export'!F3="三厢轿车",'Data Export'!F3="掀背轿车",'Data Export'!F3="旅行车",'Data Export'!F3="微型车",'Data Export'!F3="硬顶跑车",'Data Export'!F3="敞蓬车",'Data Export'!F3="Targa"),"轿车",IF(OR('Data Export'!F3="小型MPV",'Data Export'!F3="客车"),"MPV",IF('Data Export'!F3="运动型多功能车","SUV","其他")))) -> 轿车 | K3: =IF(OR(D3="",NOT(F3=1)),"",1+SUMPRODUCT(($F$2:$F$1001=1)*($D$2:$D$1001>D3))+COUNTIFS($F$2:F3,1,$D$2:D3,D3)-1) -> 6 | L3: =IF(OR(D3="",NOT(G3="轿车")),"",1+SUMPRODUCT(($G$2:$G$1001="轿车")*($D$2:$D$1001>D3))+COUNTIFS($G$2:G3,"轿车",$D$2:D3,D3)-1) -> 3 | M3: =IF(OR(D3="",NOT(G3="MPV")),"",1+SUMPRODUCT(($G$2:$G$1001="MPV")*($D$2:$D$1001>D3))+COUNTIFS($G$2:G3,"MPV",$D$2:D3,D3)-1) | N3: =IF(OR(D3="",NOT(G3="SUV")),"",1+SUMPRODUCT(($G$2:$G$1001="SUV")*($D$2:$D$1001>D3))+COUNTIFS($G$2:G3,"SUV",$D$2:D3,D3)-1) | O3: =IF(OR(D3="",NOT(AND(F3=1,G3="轿车"))),"",1+SUMPRODUCT(($F$2:$F$1001=1)*($G$2:$G$1001="轿车")*($D$2:$D$1001>D3))+COUNTIFS($F$2:F3,1,$G$2:G3,"轿车",$D$2:D3,D3)-1) -> 2 | P3: =IF(OR(D3="",NOT(AND(F3=1,G3="MPV"))),"",1+SUMPRODUCT(($F$2:$F$1001=1)*($G$2:$G$1001="MPV")*($D$2:$D$1001>D3))+COUNTIFS($F$2:F3,1,$G$2:G3,"MPV",$D$2:D3,D3)-1) | Q3: =IF(OR(D3="",NOT(AND(F3=1,G3="SUV"))),"",1+SUMPRODUCT(($F$2:$F$1001=1)*($G$2:$G$1001="SUV")*($D$2:$D$1001>D3))+COUNTIFS($F$2:F3,1,$G$2:G3,"SUV",$D$2:D3,D3)-1) | S3: 轿车：三厢/掀背/旅行/微型/跑车/敞篷/Targa；MPV：小型MPV/客车；SUV：运动型多功能车。
A4: =IFERROR(INDEX($H$2:$H$3000,MATCH(0,INDEX(COUNTIF($A$1:A3,$H$2:$H$3000)+($H$2:$H$3000=""),0,0),0)),"") -> AION♦V | B4: =IF(A4="","",LEFT(A4,FIND("♦",A4)-1)) -> AION | C4: =IF(A4="","",MID(A4,FIND("♦",A4)+1,999)) -> V | D4: =IF(A4="","",SUMIF($H$2:$H$3000,A4,$I$2:$I$3000)) -> 554 | E4: =IF(D4="","",_xlfn.RANK.EQ(D4,$D$2:$D$1001,0)+COUNTIF($D$2:D4,D4)-1) -> 23 | F4: =IF(B4="","",--(COUNTIF(CN_Brands!$A$2:$A$300,UPPER(B4))>0)) -> 1 | G4: =IF(A4="","",IFERROR(INDEX($J$2:$J$3000,MATCH(A4,$H$2:$H$3000,0)),"其他")) -> SUV | H4: =IF(AND('Data Export'!A4=前十整体车型排名!$B$2,'Data Export'!B4=前十整体车型排名!$B$3,'Data Export'!D4<>""),UPPER('Data Export'!C4)&"♦"&'Data Export'!D4,"") -> AION♦UT | I4: =IF(H4="","",IFERROR(INDEX('Data Export'!G4:CZ4,1,MATCH(前十整体车型排名!$B$4,'Data Export'!$G$1:$CZ$1,0)),0)) -> 338 | J4: =IF(H4="","",IF(OR('Data Export'!F4="三厢轿车",'Data Export'!F4="掀背轿车",'Data Export'!F4="旅行车",'Data Export'!F4="微型车",'Data Export'!F4="硬顶跑车",'Data Export'!F4="敞蓬车",'Data Export'!F4="Targa"),"轿车",IF(OR('Data Export'!F4="小型MPV",'Data Export'!F4="客车"),"MPV",IF('Data Export'!F4="运动型多功能车","SUV","其他")))) -> 轿车 | K4: =IF(OR(D4="",NOT(F4=1)),"",1+SUMPRODUCT(($F$2:$F$1001=1)*($D$2:$D$1001>D4))+COUNTIFS($F$2:F4,1,$D$2:D4,D4)-1) -> 12 | L4: =IF(OR(D4="",NOT(G4="轿车")),"",1+SUMPRODUCT(($G$2:$G$1001="轿车")*($D$2:$D$1001>D4))+COUNTIFS($G$2:G4,"轿车",$D$2:D4,D4)-1) | M4: =IF(OR(D4="",NOT(G4="MPV")),"",1+SUMPRODUCT(($G$2:$G$1001="MPV")*($D$2:$D$1001>D4))+COUNTIFS($G$2:G4,"MPV",$D$2:D4,D4)-1) | N4: =IF(OR(D4="",NOT(G4="SUV")),"",1+SUMPRODUCT(($G$2:$G$1001="SUV")*($D$2:$D$1001>D4))+COUNTIFS($G$2:G4,"SUV",$D$2:D4,D4)-1) -> 16 | O4: =IF(OR(D4="",NOT(AND(F4=1,G4="轿车"))),"",1+SUMPRODUCT(($F$2:$F$1001=1)*($G$2:$G$1001="轿车")*($D$2:$D$1001>D4))+COUNTIFS($F$2:F4,1,$G$2:G4,"轿车",$D$2:D4,D4)-1) | P4: =IF(OR(D4="",NOT(AND(F4=1,G4="MPV"))),"",1+SUMPRODUCT(($F$2:$F$1001=1)*($G$2:$G$1001="MPV")*($D$2:$D$1001>D4))+COUNTIFS($F$2:F4,1,$G$2:G4,"MPV",$D$2:D4,D4)-1) | Q4: =IF(OR(D4="",NOT(AND(F4=1,G4="SUV"))),"",1+SUMPRODUCT(($F$2:$F$1001=1)*($G$2:$G$1001="SUV")*($D$2:$D$1001>D4))+COUNTIFS($F$2:F4,1,$G$2:G4,"SUV",$D$2:D4,D4)-1) -> 9 | S4: 支持 Data Export 第2至3000行、最多1000个品牌+车型组合。
A5: =IFERROR(INDEX($H$2:$H$3000,MATCH(0,INDEX(COUNTIF($A$1:A4,$H$2:$H$3000)+($H$2:$H$3000=""),0,0),0)),"") -> AION♦Y PLUS | B5: =IF(A5="","",LEFT(A5,FIND("♦",A5)-1)) -> AION | C5: =IF(A5="","",MID(A5,FIND("♦",A5)+1,999)) -> Y PLUS | D5: =IF(A5="","",SUMIF($H$2:$H$3000,A5,$I$2:$I$3000)) -> 112 | E5: =IF(D5="","",_xlfn.RANK.EQ(D5,$D$2:$D$1001,0)+COUNTIF($D$2:D5,D5)-1) -> 69 | F5: =IF(B5="","",--(COUNTIF(CN_Brands!$A$2:$A$300,UPPER(B5))>0)) -> 1 | G5: =IF(A5="","",IFERROR(INDEX($J$2:$J$3000,MATCH(A5,$H$2:$H$3000,0)),"其他")) -> SUV | H5: =IF(AND('Data Export'!A5=前十整体车型排名!$B$2,'Data Export'!B5=前十整体车型排名!$B$3,'Data Export'!D5<>""),UPPER('Data Export'!C5)&"♦"&'Data Export'!D5,"") -> AION♦V | I5: =IF(H5="","",IFERROR(INDEX('Data Export'!G5:CZ5,1,MATCH(前十整体车型排名!$B$4,'Data Export'!$G$1:$CZ$1,0)),0)) -> 346 | J5: =IF(H5="","",IF(OR('Data Export'!F5="三厢轿车",'Data Export'!F5="掀背轿车",'Data Export'!F5="旅行车",'Data Export'!F5="微型车",'Data Export'!F5="硬顶跑车",'Data Export'!F5="敞蓬车",'Data Export'!F5="Targa"),"轿车",IF(OR('Data Export'!F5="小型MPV",'Data Export'!F5="客车"),"MPV",IF('Data Export'!F5="运动型多功能车","SUV","其他")))) -> SUV | K5: =IF(OR(D5="",NOT(F5=1)),"",1+SUMPRODUCT(($F$2:$F$1001=1)*($D$2:$D$1001>D5))+COUNTIFS($F$2:F5,1,$D$2:D5,D5)-1) -> 35 | L5: =IF(OR(D5="",NOT(G5="轿车")),"",1+SUMPRODUCT(($G$2:$G$1001="轿车")*($D$2:$D$1001>D5))+COUNTIFS($G$2:G5,"轿车",$D$2:D5,D5)-1) | M5: =IF(OR(D5="",NOT(G5="MPV")),"",1+SUMPRODUCT(($G$2:$G$1001="MPV")*($D$2:$D$1001>D5))+COUNTIFS($G$2:G5,"MPV",$D$2:D5,D5)-1) | N5: =IF(OR(D5="",NOT(G5="SUV")),"",1+SUMPRODUCT(($G$2:$G$1001="SUV")*($D$2:$D$1001>D5))+COUNTIFS($G$2:G5,"SUV",$D$2:D5,D5)-1) -> 36 | O5: =IF(OR(D5="",NOT(AND(F5=1,G5="轿车"))),"",1+SUMPRODUCT(($F$2:$F$1001=1)*($G$2:$G$1001="轿车")*($D$2:$D$1001>D5))+COUNTIFS($F$2:F5,1,$G$2:G5,"轿车",$D$2:D5,D5)-1) | P5: =IF(OR(D5="",NOT(AND(F5=1,G5="MPV"))),"",1+SUMPRODUCT(($F$2:$F$1001=1)*($G$2:$G$1001="MPV")*($D$2:$D$1001>D5))+COUNTIFS($F$2:F5,1,$G$2:G5,"MPV",$D$2:D5,D5)-1) | Q5: =IF(OR(D5="",NOT(AND(F5=1,G5="SUV"))),"",1+SUMPRODUCT(($F$2:$F$1001=1)*($G$2:$G$1001="SUV")*($D$2:$D$1001>D5))+COUNTIFS($F$2:F5,1,$G$2:G5,"SUV",$D$2:D5,D5)-1) -> 23
A6: =IFERROR(INDEX($H$2:$H$3000,MATCH(0,INDEX(COUNTIF($A$1:A5,$H$2:$H$3000)+($H$2:$H$3000=""),0,0),0)),"") -> ASTON MARTIN♦DB11 | B6: =IF(A6="","",LEFT(A6,FIND("♦",A6)-1)) -> ASTON MARTIN | C6: =IF(A6="","",MID(A6,FIND("♦",A6)+1,999)) -> DB11 | D6: =IF(A6="","",SUMIF($H$2:$H$3000,A6,$I$2:$I$3000)) -> 0 | E6: =IF(D6="","",_xlfn.RANK.EQ(D6,$D$2:$D$1001,0)+COUNTIF($D$2:D6,D6)-1) -> 264 | F6: =IF(B6="","",--(COUNTIF(CN_Brands!$A$2:$A$300,UPPER(B6))>0)) -> 0 | G6: =IF(A6="","",IFERROR(INDEX($J$2:$J$3000,MATCH(A6,$H$2:$H$3000,0)),"其他")) -> 轿车 | H6: =IF(AND('Data Export'!A6=前十整体车型排名!$B$2,'Data Export'!B6=前十整体车型排名!$B$3,'Data Export'!D6<>""),UPPER('Data Export'!C6)&"♦"&'Data Export'!D6,"") -> AION♦V | I6: =IF(H6="","",IFERROR(INDEX('Data Export'!G6:CZ6,1,MATCH(前十整体车型排名!$B$4,'Data Export'!$G$1:$CZ$1,0)),0)) -> 208 | J6: =IF(H6="","",IF(OR('Data Export'!F6="三厢轿车",'Data Export'!F6="掀背轿车",'Data Export'!F6="旅行车",'Data Export'!F6="微型车",'Data Export'!F6="硬顶跑车",'Data Export'!F6="敞蓬车",'Data Export'!F6="Targa"),"轿车",IF(OR('Data Export'!F6="小型MPV",'Data Export'!F6="客车"),"MPV",IF('Data Export'!F6="运动型多功能车","SUV","其他")))) -> SUV | K6: =IF(OR(D6="",NOT(F6=1)),"",1+SUMPRODUCT(($F$2:$F$1001=1)*($D$2:$D$1001>D6))+COUNTIFS($F$2:F6,1,$D$2:D6,D6)-1) | L6: =IF(OR(D6="",NOT(G6="轿车")),"",1+SUMPRODUCT(($G$2:$G$1001="轿车")*($D$2:$D$1001>D6))+COUNTIFS($G$2:G6,"轿车",$D$2:D6,D6)-1) -> 82 | M6: =IF(OR(D6="",NOT(G6="MPV")),"",1+SUMPRODUCT(($G$2:$G$1001="MPV")*($D$2:$D$1001>D6))+COUNTIFS($G$2:G6,"MPV",$D$2:D6,D6)-1) | N6: =IF(OR(D6="",NOT(G6="SUV")),"",1+SUMPRODUCT(($G$2:$G$1001="SUV")*($D$2:$D$1001>D6))+COUNTIFS($G$2:G6,"SUV",$D$2:D6,D6)-1) | O6: =IF(OR(D6="",NOT(AND(F6=1,G6="轿车"))),"",1+SUMPRODUCT(($F$2:$F$1001=1)*($G$2:$G$1001="轿车")*($D$2:$D$1001>D6))+COUNTIFS($F$2:F6,1,$G$2:G6,"轿车",$D$2:D6,D6)-1) | P6: =IF(OR(D6="",NOT(AND(F6=1,G6="MPV"))),"",1+SUMPRODUCT(($F$2:$F$1001=1)*($G$2:$G$1001="MPV")*($D$2:$D$1001>D6))+COUNTIFS($F$2:F6,1,$G$2:G6,"MPV",$D$2:D6,D6)-1) | Q6: =IF(OR(D6="",NOT(AND(F6=1,G6="SUV"))),"",1+SUMPRODUCT(($F$2:$F$1001=1)*($G$2:$G$1001="SUV")*($D$2:$D$1001>D6))+COUNTIFS($F$2:F6,1,$G$2:G6,"SUV",$D$2:D6,D6)-1)
A7: =IFERROR(INDEX($H$2:$H$3000,MATCH(0,INDEX(COUNTIF($A$1:A6,$H$2:$H$3000)+($H$2:$H$3000=""),0,0),0)),"") -> ASTON MARTIN♦DB12 | B7: =IF(A7="","",LEFT(A7,FIND("♦",A7)-1)) -> ASTON MARTIN | C7: =IF(A7="","",MID(A7,FIND("♦",A7)+1,999)) -> DB12 | D7: =IF(A7="","",SUMIF($H$2:$H$3000,A7,$I$2:$I$3000)) -> 1 | E7: =IF(D7="","",_xlfn.RANK.EQ(D7,$D$2:$D$1001,0)+COUNTIF($D$2:D7,D7)-1) -> 218 | F7: =IF(B7="","",--(COUNTIF(CN_Brands!$A$2:$A$300,UPPER(B7))>0)) -> 0 | G7: =IF(A7="","",IFERROR(INDEX($J$2:$J$3000,MATCH(A7,$H$2:$H$3000,0)),"其他")) -> 轿车 | H7: =IF(AND('Data Export'!A7=前十整体车型排名!$B$2,'Data Export'!B7=前十整体车型排名!$B$3,'Data Export'!D7<>""),UPPER('Data Export'!C7)&"♦"&'Data Export'!D7,"") -> AION♦Y PLUS | I7: =IF(H7="","",IFERROR(INDEX('Data Export'!G7:CZ7,1,MATCH(前十整体车型排名!$B$4,'Data Export'!$G$1:$CZ$1,0)),0)) -> 12 | J7: =IF(H7="","",IF(OR('Data Export'!F7="三厢轿车",'Data Export'!F7="掀背轿车",'Data Export'!F7="旅行车",'Data Export'!F7="微型车",'Data Export'!F7="硬顶跑车",'Data Export'!F7="敞蓬车",'Data Export'!F7="Targa"),"轿车",IF(OR('Data Export'!F7="小型MPV",'Data Export'!F7="客车"),"MPV",IF('Data Export'!F7="运动型多功能车","SUV","其他")))) -> SUV | K7: =IF(OR(D7="",NOT(F7=1)),"",1+SUMPRODUCT(($F$2:$F$1001=1)*($D$2:$D$1001>D7))+COUNTIFS($F$2:F7,1,$D$2:D7,D7)-1) | L7: =IF(OR(D7="",NOT(G7="轿车")),"",1+SUMPRODUCT(($G$2:$G$1001="轿车")*($D$2:$D$1001>D7))+COUNTIFS($G$2:G7,"轿车",$D$2:D7,D7)-1) -> 64 | M7: =IF(OR(D7="",NOT(G7="MPV")),"",1+SUMPRODUCT(($G$2:$G$1001="MPV")*($D$2:$D$1001>D7))+COUNTIFS($G$2:G7,"MPV",$D$2:D7,D7)-1) | N7: =IF(OR(D7="",NOT(G7="SUV")),"",1+SUMPRODUCT(($G$2:$G$1001="SUV")*($D$2:$D$1001>D7))+COUNTIFS($G$2:G7,"SUV",$D$2:D7,D7)-1) | O7: =IF(OR(D7="",NOT(AND(F7=1,G7="轿车"))),"",1+SUMPRODUCT(($F$2:$F$1001=1)*($G$2:$G$1001="轿车")*($D$2:$D$1001>D7))+COUNTIFS($F$2:F7,1,$G$2:G7,"轿车",$D$2:D7,D7)-1) | P7: =IF(OR(D7="",NOT(AND(F7=1,G7="MPV"))),"",1+SUMPRODUCT(($F$2:$F$1001=1)*($G$2:$G$1001="MPV")*($D$2:$D$1001>D7))+COUNTIFS($F$2:F7,1,$G$2:G7,"MPV",$D$2:D7,D7)-1) | Q7: =IF(OR(D7="",NOT(AND(F7=1,G7="SUV"))),"",1+SUMPRODUCT(($F$2:$F$1001=1)*($G$2:$G$1001="SUV")*($D$2:$D$1001>D7))+COUNTIFS($F$2:F7,1,$G$2:G7,"SUV",$D$2:D7,D7)-1)
A8: =IFERROR(INDEX($H$2:$H$3000,MATCH(0,INDEX(COUNTIF($A$1:A7,$H$2:$H$3000)+($H$2:$H$3000=""),0,0),0)),"") -> ASTON MARTIN♦DBX | B8: =IF(A8="","",LEFT(A8,FIND("♦",A8)-1)) -> ASTON MARTIN | C8: =IF(A8="","",MID(A8,FIND("♦",A8)+1,999)) -> DBX | D8: =IF(A8="","",SUMIF($H$2:$H$3000,A8,$I$2:$I$3000)) -> 0 | E8: =IF(D8="","",_xlfn.RANK.EQ(D8,$D$2:$D$1001,0)+COUNTIF($D$2:D8,D8)-1) -> 265 | F8: =IF(B8="","",--(COUNTIF(CN_Brands!$A$2:$A$300,UPPER(B8))>0)) -> 0 | G8: =IF(A8="","",IFERROR(INDEX($J$2:$J$3000,MATCH(A8,$H$2:$H$3000,0)),"其他")) -> SUV | H8: =IF(AND('Data Export'!A8=前十整体车型排名!$B$2,'Data Export'!B8=前十整体车型排名!$B$3,'Data Export'!D8<>""),UPPER('Data Export'!C8)&"♦"&'Data Export'!D8,"") -> AION♦Y PLUS | I8: =IF(H8="","",IFERROR(INDEX('Data Export'!G8:CZ8,1,MATCH(前十整体车型排名!$B$4,'Data Export'!$G$1:$CZ$1,0)),0)) -> 93 | J8: =IF(H8="","",IF(OR('Data Export'!F8="三厢轿车",'Data Export'!F8="掀背轿车",'Data Export'!F8="旅行车",'Data Export'!F8="微型车",'Data Export'!F8="硬顶跑车",'Data Export'!F8="敞蓬车",'Data Export'!F8="Targa"),"轿车",IF(OR('Data Export'!F8="小型MPV",'Data Export'!F8="客车"),"MPV",IF('Data Export'!F8="运动型多功能车","SUV","其他")))) -> SUV | K8: =IF(OR(D8="",NOT(F8=1)),"",1+SUMPRODUCT(($F$2:$F$1001=1)*($D$2:$D$1001>D8))+COUNTIFS($F$2:F8,1,$D$2:D8,D8)-1) | L8: =IF(OR(D8="",NOT(G8="轿车")),"",1+SUMPRODUCT(($G$2:$G$1001="轿车")*($D$2:$D$1001>D8))+COUNTIFS($G$2:G8,"轿车",$D$2:D8,D8)-1) | M8: =IF(OR(D8="",NOT(G8="MPV")),"",1+SUMPRODUCT(($G$2:$G$1001="MPV")*($D$2:$D$1001>D8))+COUNTIFS($G$2:G8,"MPV",$D$2:D8,D8)-1) | N8: =IF(OR(D8="",NOT(G8="SUV")),"",1+SUMPRODUCT(($G$2:$G$1001="SUV")*($D$2:$D$1001>D8))+COUNTIFS($G$2:G8,"SUV",$D$2:D8,D8)-1) -> 129 | O8: =IF(OR(D8="",NOT(AND(F8=1,G8="轿车"))),"",1+SUMPRODUCT(($F$2:$F$1001=1)*($G$2:$G$1001="轿车")*($D$2:$D$1001>D8))+COUNTIFS($F$2:F8,1,$G$2:G8,"轿车",$D$2:D8,D8)-1) | P8: =IF(OR(D8="",NOT(AND(F8=1,G8="MPV"))),"",1+SUMPRODUCT(($F$2:$F$1001=1)*($G$2:$G$1001="MPV")*($D$2:$D$1001>D8))+COUNTIFS($F$2:F8,1,$G$2:G8,"MPV",$D$2:D8,D8)-1) | Q8: =IF(OR(D8="",NOT(AND(F8=1,G8="SUV"))),"",1+SUMPRODUCT(($F$2:$F$1001=1)*($G$2:$G$1001="SUV")*($D$2:$D$1001>D8))+COUNTIFS($F$2:F8,1,$G$2:G8,"SUV",$D$2:D8,D8)-1)
A9: =IFERROR(INDEX($H$2:$H$3000,MATCH(0,INDEX(COUNTIF($A$1:A8,$H$2:$H$3000)+($H$2:$H$3000=""),0,0),0)),"") -> ASTON MARTIN♦RAPIDE | B9: =IF(A9="","",LEFT(A9,FIND("♦",A9)-1)) -> ASTON MARTIN | C9: =IF(A9="","",MID(A9,FIND("♦",A9)+1,999)) -> RAPIDE | D9: =IF(A9="","",SUMIF($H$2:$H$3000,A9,$I$2:$I$3000)) -> 0 | E9: =IF(D9="","",_xlfn.RANK.EQ(D9,$D$2:$D$1001,0)+COUNTIF($D$2:D9,D9)-1) -> 266 | F9: =IF(B9="","",--(COUNTIF(CN_Brands!$A$2:$A$300,UPPER(B9))>0)) -> 0 | G9: =IF(A9="","",IFERROR(INDEX($J$2:$J$3000,MATCH(A9,$H$2:$H$3000,0)),"其他")) -> 轿车 | H9: =IF(AND('Data Export'!A9=前十整体车型排名!$B$2,'Data Export'!B9=前十整体车型排名!$B$3,'Data Export'!D9<>""),UPPER('Data Export'!C9)&"♦"&'Data Export'!D9,"") -> AION♦Y PLUS | I9: =IF(H9="","",IFERROR(INDEX('Data Export'!G9:CZ9,1,MATCH(前十整体车型排名!$B$4,'Data Export'!$G$1:$CZ$1,0)),0)) -> 7 | J9: =IF(H9="","",IF(OR('Data Export'!F9="三厢轿车",'Data Export'!F9="掀背轿车",'Data Export'!F9="旅行车",'Data Export'!F9="微型车",'Data Export'!F9="硬顶跑车",'Data Export'!F9="敞蓬车",'Data Export'!F9="Targa"),"轿车",IF(OR('Data Export'!F9="小型MPV",'Data Export'!F9="客车"),"MPV",IF('Data Export'!F9="运动型多功能车","SUV","其他")))) -> SUV | K9: =IF(OR(D9="",NOT(F9=1)),"",1+SUMPRODUCT(($F$2:$F$1001=1)*($D$2:$D$1001>D9))+COUNTIFS($F$2:F9,1,$D$2:D9,D9)-1) | L9: =IF(OR(D9="",NOT(G9="轿车")),"",1+SUMPRODUCT(($G$2:$G$1001="轿车")*($D$2:$D$1001>D9))+COUNTIFS($G$2:G9,"轿车",$D$2:D9,D9)-1) -> 83 | M9: =IF(OR(D9="",NOT(G9="MPV")),"",1+SUMPRODUCT(($G$2:$G$1001="MPV")*($D$2:$D$1001>D9))+COUNTIFS($G$2:G9,"MPV",$D$2:D9,D9)-1) | N9: =IF(OR(D9="",NOT(G9="SUV")),"",1+SUMPRODUCT(($G$2:$G$1001="SUV")*($D$2:$D$1001>D9))+COUNTIFS($G$2:G9,"SUV",$D$2:D9,D9)-1) | O9: =IF(OR(D9="",NOT(AND(F9=1,G9="轿车"))),"",1+SUMPRODUCT(($F$2:$F$1001=1)*($G$2:$G$1001="轿车")*($D$2:$D$1001>D9))+COUNTIFS($F$2:F9,1,$G$2:G9,"轿车",$D$2:D9,D9)-1) | P9: =IF(OR(D9="",NOT(AND(F9=1,G9="MPV"))),"",1+SUMPRODUCT(($F$2:$F$1001=1)*($G$2:$G$1001="MPV")*($D$2:$D$1001>D9))+COUNTIFS($F$2:F9,1,$G$2:G9,"MPV",$D$2:D9,D9)-1) | Q9: =IF(OR(D9="",NOT(AND(F9=1,G9="SUV"))),"",1+SUMPRODUCT(($F$2:$F$1001=1)*($G$2:$G$1001="SUV")*($D$2:$D$1001>D9))+COUNTIFS($F$2:F9,1,$G$2:G9,"SUV",$D$2:D9,D9)-1)
A10: =IFERROR(INDEX($H$2:$H$3000,MATCH(0,INDEX(COUNTIF($A$1:A9,$H$2:$H$3000)+($H$2:$H$3000=""),0,0),0)),"") -> ASTON MARTIN♦VANQUISH | B10: =IF(A10="","",LEFT(A10,FIND("♦",A10)-1)) -> ASTON MARTIN | C10: =IF(A10="","",MID(A10,FIND("♦",A10)+1,999)) -> VANQUISH | D10: =IF(A10="","",SUMIF($H$2:$H$3000,A10,$I$2:$I$3000)) -> 0 | E10: =IF(D10="","",_xlfn.RANK.EQ(D10,$D$2:$D$1001,0)+COUNTIF($D$2:D10,D10)-1) -> 267 | F10: =IF(B10="","",--(COUNTIF(CN_Brands!$A$2:$A$300,UPPER(B10))>0)) -> 0 | G10: =IF(A10="","",IFERROR(INDEX($J$2:$J$3000,MATCH(A10,$H$2:$H$3000,0)),"其他")) -> 轿车 | H10: =IF(AND('Data Export'!A10=前十整体车型排名!$B$2,'Data Export'!B10=前十整体车型排名!$B$3,'Data Export'!D10<>""),UPPER('Data Export'!C10)&"♦"&'Data Export'!D10,"") -> ASTON MARTIN♦DB11 | I10: =IF(H10="","",IFERROR(INDEX('Data Export'!G10:CZ10,1,MATCH(前十整体车型排名!$B$4,'Data Export'!$G$1:$CZ$1,0)),0)) -> 0 | J10: =IF(H10="","",IF(OR('Data Export'!F10="三厢轿车",'Data Export'!F10="掀背轿车",'Data Export'!F10="旅行车",'Data Export'!F10="微型车",'Data Export'!F10="硬顶跑车",'Data Export'!F10="敞蓬车",'Data Export'!F10="Targa"),"轿车",IF(OR('Data Export'!F10="小型MPV",'Data Export'!F10="客车"),"MPV",IF('Data Export'!F10="运动型多功能车","SUV","其他")))) -> 轿车 | K10: =IF(OR(D10="",NOT(F10=1)),"",1+SUMPRODUCT(($F$2:$F$1001=1)*($D$2:$D$1001>D10))+COUNTIFS($F$2:F10,1,$D$2:D10,D10)-1) | L10: =IF(OR(D10="",NOT(G10="轿车")),"",1+SUMPRODUCT(($G$2:$G$1001="轿车")*($D$2:$D$1001>D10))+COUNTIFS($G$2:G10,"轿车",$D$2:D10,D10)-1) -> 84 | M10: =IF(OR(D10="",NOT(G10="MPV")),"",1+SUMPRODUCT(($G$2:$G$1001="MPV")*($D$2:$D$1001>D10))+COUNTIFS($G$2:G10,"MPV",$D$2:D10,D10)-1) | N10: =IF(OR(D10="",NOT(G10="SUV")),"",1+SUMPRODUCT(($G$2:$G$1001="SUV")*($D$2:$D$1001>D10))+COUNTIFS($G$2:G10,"SUV",$D$2:D10,D10)-1) | O10: =IF(OR(D10="",NOT(AND(F10=1,G10="轿车"))),"",1+SUMPRODUCT(($F$2:$F$1001=1)*($G$2:$G$1001="轿车")*($D$2:$D$1001>D10))+COUNTIFS($F$2:F10,1,$G$2:G10,"轿车",$D$2:D10,D10)-1) | P10: =IF(OR(D10="",NOT(AND(F10=1,G10="MPV"))),"",1+SUMPRODUCT(($F$2:$F$1001=1)*($G$2:$G$1001="MPV")*($D$2:$D$1001>D10))+COUNTIFS($F$2:F10,1,$G$2:G10,"MPV",$D$2:D10,D10)-1) | Q10: =IF(OR(D10="",NOT(AND(F10=1,G10="SUV"))),"",1+SUMPRODUCT(($F$2:$F$1001=1)*($G$2:$G$1001="SUV")*($D$2:$D$1001>D10))+COUNTIFS($F$2:F10,1,$G$2:G10,"SUV",$D$2:D10,D10)-1)
A11: =IFERROR(INDEX($H$2:$H$3000,MATCH(0,INDEX(COUNTIF($A$1:A10,$H$2:$H$3000)+($H$2:$H$3000=""),0,0),0)),"") -> ASTON MARTIN♦VANTAGE | B11: =IF(A11="","",LEFT(A11,FIND("♦",A11)-1)) -> ASTON MARTIN | C11: =IF(A11="","",MID(A11,FIND("♦",A11)+1,999)) -> VANTAGE | D11: =IF(A11="","",SUMIF($H$2:$H$3000,A11,$I$2:$I$3000)) -> 0 | E11: =IF(D11="","",_xlfn.RANK.EQ(D11,$D$2:$D$1001,0)+COUNTIF($D$2:D11,D11)-1) -> 268 | F11: =IF(B11="","",--(COUNTIF(CN_Brands!$A$2:$A$300,UPPER(B11))>0)) -> 0 | G11: =IF(A11="","",IFERROR(INDEX($J$2:$J$3000,MATCH(A11,$H$2:$H$3000,0)),"其他")) -> 轿车 | H11: =IF(AND('Data Export'!A11=前十整体车型排名!$B$2,'Data Export'!B11=前十整体车型排名!$B$3,'Data Export'!D11<>""),UPPER('Data Export'!C11)&"♦"&'Data Export'!D11,"") -> ASTON MARTIN♦DB12 | I11: =IF(H11="","",IFERROR(INDEX('Data Export'!G11:CZ11,1,MATCH(前十整体车型排名!$B$4,'Data Export'!$G$1:$CZ$1,0)),0)) -> 1 | J11: =IF(H11="","",IF(OR('Data Export'!F11="三厢轿车",'Data Export'!F11="掀背轿车",'Data Export'!F11="旅行车",'Data Export'!F11="微型车",'Data Export'!F11="硬顶跑车",'Data Export'!F11="敞蓬车",'Data Export'!F11="Targa"),"轿车",IF(OR('Data Export'!F11="小型MPV",'Data Export'!F11="客车"),"MPV",IF('Data Export'!F11="运动型多功能车","SUV","其他")))) -> 轿车 | K11: =IF(OR(D11="",NOT(F11=1)),"",1+SUMPRODUCT(($F$2:$F$1001=1)*($D$2:$D$1001>D11))+COUNTIFS($F$2:F11,1,$D$2:D11,D11)-1) | L11: =IF(OR(D11="",NOT(G11="轿车")),"",1+SUMPRODUCT(($G$2:$G$1001="轿车")*($D$2:$D$1001>D11))+COUNTIFS($G$2:G11,"轿车",$D$2:D11,D11)-1) -> 85 | M11: =IF(OR(D11="",NOT(G11="MPV")),"",1+SUMPRODUCT(($G$2:$G$1001="MPV")*($D$2:$D$1001>D11))+COUNTIFS($G$2:G11,"MPV",$D$2:D11,D11)-1) | N11: =IF(OR(D11="",NOT(G11="SUV")),"",1+SUMPRODUCT(($G$2:$G$1001="SUV")*($D$2:$D$1001>D11))+COUNTIFS($G$2:G11,"SUV",$D$2:D11,D11)-1) | O11: =IF(OR(D11="",NOT(AND(F11=1,G11="轿车"))),"",1+SUMPRODUCT(($F$2:$F$1001=1)*($G$2:$G$1001="轿车")*($D$2:$D$1001>D11))+COUNTIFS($F$2:F11,1,$G$2:G11,"轿车",$D$2:D11,D11)-1) | P11: =IF(OR(D11="",NOT(AND(F11=1,G11="MPV"))),"",1+SUMPRODUCT(($F$2:$F$1001=1)*($G$2:$G$1001="MPV")*($D$2:$D$1001>D11))+COUNTIFS($F$2:F11,1,$G$2:G11,"MPV",$D$2:D11,D11)-1) | Q11: =IF(OR(D11="",NOT(AND(F11=1,G11="SUV"))),"",1+SUMPRODUCT(($F$2:$F$1001=1)*($G$2:$G$1001="SUV")*($D$2:$D$1001>D11))+COUNTIFS($F$2:F11,1,$G$2:G11,"SUV",$D$2:D11,D11)-1)
A12: =IFERROR(INDEX($H$2:$H$3000,MATCH(0,INDEX(COUNTIF($A$1:A11,$H$2:$H$3000)+($H$2:$H$3000=""),0,0),0)),"") -> AUDI♦A1 | B12: =IF(A12="","",LEFT(A12,FIND("♦",A12)-1)) -> AUDI | C12: =IF(A12="","",MID(A12,FIND("♦",A12)+1,999)) -> A1 | D12: =IF(A12="","",SUMIF($H$2:$H$3000,A12,$I$2:$I$3000)) -> 0 | E12: =IF(D12="","",_xlfn.RANK.EQ(D12,$D$2:$D$1001,0)+COUNTIF($D$2:D12,D12)-1) -> 269 | F12: =IF(B12="","",--(COUNTIF(CN_Brands!$A$2:$A$300,UPPER(B12))>0)) -> 0 | G12: =IF(A12="","",IFERROR(INDEX($J$2:$J$3000,MATCH(A12,$H$2:$H$3000,0)),"其他")) -> 轿车 | H12: =IF(AND('Data Export'!A12=前十整体车型排名!$B$2,'Data Export'!B12=前十整体车型排名!$B$3,'Data Export'!D12<>""),UPPER('Data Export'!C12)&"♦"&'Data Export'!D12,"") -> ASTON MARTIN♦DBX | I12: =IF(H12="","",IFERROR(INDEX('Data Export'!G12:CZ12,1,MATCH(前十整体车型排名!$B$4,'Data Export'!$G$1:$CZ$1,0)),0)) -> 0 | J12: =IF(H12="","",IF(OR('Data Export'!F12="三厢轿车",'Data Export'!F12="掀背轿车",'Data Export'!F12="旅行车",'Data Export'!F12="微型车",'Data Export'!F12="硬顶跑车",'Data Export'!F12="敞蓬车",'Data Export'!F12="Targa"),"轿车",IF(OR('Data Export'!F12="小型MPV",'Data Export'!F12="客车"),"MPV",IF('Data Export'!F12="运动型多功能车","SUV","其他")))) -> SUV | K12: =IF(OR(D12="",NOT(F12=1)),"",1+SUMPRODUCT(($F$2:$F$1001=1)*($D$2:$D$1001>D12))+COUNTIFS($F$2:F12,1,$D$2:D12,D12)-1) | L12: =IF(OR(D12="",NOT(G12="轿车")),"",1+SUMPRODUCT(($G$2:$G$1001="轿车")*($D$2:$D$1001>D12))+COUNTIFS($G$2:G12,"轿车",$D$2:D12,D12)-1) -> 86 | M12: =IF(OR(D12="",NOT(G12="MPV")),"",1+SUMPRODUCT(($G$2:$G$1001="MPV")*($D$2:$D$1001>D12))+COUNTIFS($G$2:G12,"MPV",$D$2:D12,D12)-1) | N12: =IF(OR(D12="",NOT(G12="SUV")),"",1+SUMPRODUCT(($G$2:$G$1001="SUV")*($D$2:$D$1001>D12))+COUNTIFS($G$2:G12,"SUV",$D$2:D12,D12)-1) | O12: =IF(OR(D12="",NOT(AND(F12=1,G12="轿车"))),"",1+SUMPRODUCT(($F$2:$F$1001=1)*($G$2:$G$1001="轿车")*($D$2:$D$1001>D12))+COUNTIFS($F$2:F12,1,$G$2:G12,"轿车",$D$2:D12,D12)-1) | P12: =IF(OR(D12="",NOT(AND(F12=1,G12="MPV"))),"",1+SUMPRODUCT(($F$2:$F$1001=1)*($G$2:$G$1001="MPV")*($D$2:$D$1001>D12))+COUNTIFS($F$2:F12,1,$G$2:G12,"MPV",$D$2:D12,D12)-1) | Q12: =IF(OR(D12="",NOT(AND(F12=1,G12="SUV"))),"",1+SUMPRODUCT(($F$2:$F$1001=1)*($G$2:$G$1001="SUV")*($D$2:$D$1001>D12))+COUNTIFS($F$2:F12,1,$G$2:G12,"SUV",$D$2:D12,D12)-1)
A13: =IFERROR(INDEX($H$2:$H$3000,MATCH(0,INDEX(COUNTIF($A$1:A12,$H$2:$H$3000)+($H$2:$H$3000=""),0,0),0)),"") -> AUDI♦A3 | B13: =IF(A13="","",LEFT(A13,FIND("♦",A13)-1)) -> AUDI | C13: =IF(A13="","",MID(A13,FIND("♦",A13)+1,999)) -> A3 | D13: =IF(A13="","",SUMIF($H$2:$H$3000,A13,$I$2:$I$3000)) -> 1 | E13: =IF(D13="","",_xlfn.RANK.EQ(D13,$D$2:$D$1001,0)+COUNTIF($D$2:D13,D13)-1) -> 219 | F13: =IF(B13="","",--(COUNTIF(CN_Brands!$A$2:$A$300,UPPER(B13))>0)) -> 0 | G13: =IF(A13="","",IFERROR(INDEX($J$2:$J$3000,MATCH(A13,$H$2:$H$3000,0)),"其他")) -> 轿车 | H13: =IF(AND('Data Export'!A13=前十整体车型排名!$B$2,'Data Export'!B13=前十整体车型排名!$B$3,'Data Export'!D13<>""),UPPER('Data Export'!C13)&"♦"&'Data Export'!D13,"") -> ASTON MARTIN♦RAPIDE | I13: =IF(H13="","",IFERROR(INDEX('Data Export'!G13:CZ13,1,MATCH(前十整体车型排名!$B$4,'Data Export'!$G$1:$CZ$1,0)),0)) -> 0 | J13: =IF(H13="","",IF(OR('Data Export'!F13="三厢轿车",'Data Export'!F13="掀背轿车",'Data Export'!F13="旅行车",'Data Export'!F13="微型车",'Data Export'!F13="硬顶跑车",'Data Export'!F13="敞蓬车",'Data Export'!F13="Targa"),"轿车",IF(OR('Data Export'!F13="小型MPV",'Data Export'!F13="客车"),"MPV",IF('Data Export'!F13="运动型多功能车","SUV","其他")))) -> 轿车 | K13: =IF(OR(D13="",NOT(F13=1)),"",1+SUMPRODUCT(($F$2:$F$1001=1)*($D$2:$D$1001>D13))+COUNTIFS($F$2:F13,1,$D$2:D13,D13)-1) | L13: =IF(OR(D13="",NOT(G13="轿车")),"",1+SUMPRODUCT(($G$2:$G$1001="轿车")*($D$2:$D$1001>D13))+COUNTIFS($G$2:G13,"轿车",$D$2:D13,D13)-1) -> 65 | M13: =IF(OR(D13="",NOT(G13="MPV")),"",1+SUMPRODUCT(($G$2:$G$1001="MPV")*($D$2:$D$1001>D13))+COUNTIFS($G$2:G13,"MPV",$D$2:D13,D13)-1) | N13: =IF(OR(D13="",NOT(G13="SUV")),"",1+SUMPRODUCT(($G$2:$G$1001="SUV")*($D$2:$D$1001>D13))+COUNTIFS($G$2:G13,"SUV",$D$2:D13,D13)-1) | O13: =IF(OR(D13="",NOT(AND(F13=1,G13="轿车"))),"",1+SUMPRODUCT(($F$2:$F$1001=1)*($G$2:$G$1001="轿车")*($D$2:$D$1001>D13))+COUNTIFS($F$2:F13,1,$G$2:G13,"轿车",$D$2:D13,D13)-1) | P13: =IF(OR(D13="",NOT(AND(F13=1,G13="MPV"))),"",1+SUMPRODUCT(($F$2:$F$1001=1)*($G$2:$G$1001="MPV")*($D$2:$D$1001>D13))+COUNTIFS($F$2:F13,1,$G$2:G13,"MPV",$D$2:D13,D13)-1) | Q13: =IF(OR(D13="",NOT(AND(F13=1,G13="SUV"))),"",1+SUMPRODUCT(($F$2:$F$1001=1)*($G$2:$G$1001="SUV")*($D$2:$D$1001>D13))+COUNTIFS($F$2:F13,1,$G$2:G13,"SUV",$D$2:D13,D13)-1)
A14: =IFERROR(INDEX($H$2:$H$3000,MATCH(0,INDEX(COUNTIF($A$1:A13,$H$2:$H$3000)+($H$2:$H$3000=""),0,0),0)),"") -> AUDI♦A4 | B14: =IF(A14="","",LEFT(A14,FIND("♦",A14)-1)) -> AUDI | C14: =IF(A14="","",MID(A14,FIND("♦",A14)+1,999)) -> A4 | D14: =IF(A14="","",SUMIF($H$2:$H$3000,A14,$I$2:$I$3000)) -> 1 | E14: =IF(D14="","",_xlfn.RANK.EQ(D14,$D$2:$D$1001,0)+COUNTIF($D$2:D14,D14)-1) -> 220 | F14: =IF(B14="","",--(COUNTIF(CN_Brands!$A$2:$A$300,UPPER(B14))>0)) -> 0 | G14: =IF(A14="","",IFERROR(INDEX($J$2:$J$3000,MATCH(A14,$H$2:$H$3000,0)),"其他")) -> 轿车 | H14: =IF(AND('Data Export'!A14=前十整体车型排名!$B$2,'Data Export'!B14=前十整体车型排名!$B$3,'Data Export'!D14<>""),UPPER('Data Export'!C14)&"♦"&'Data Export'!D14,"") -> ASTON MARTIN♦VANQUISH | I14: =IF(H14="","",IFERROR(INDEX('Data Export'!G14:CZ14,1,MATCH(前十整体车型排名!$B$4,'Data Export'!$G$1:$CZ$1,0)),0)) -> 0 | J14: =IF(H14="","",IF(OR('Data Export'!F14="三厢轿车",'Data Export'!F14="掀背轿车",'Data Export'!F14="旅行车",'Data Export'!F14="微型车",'Data Export'!F14="硬顶跑车",'Data Export'!F14="敞蓬车",'Data Export'!F14="Targa"),"轿车",IF(OR('Data Export'!F14="小型MPV",'Data Export'!F14="客车"),"MPV",IF('Data Export'!F14="运动型多功能车","SUV","其他")))) -> 轿车 | K14: =IF(OR(D14="",NOT(F14=1)),"",1+SUMPRODUCT(($F$2:$F$1001=1)*($D$2:$D$1001>D14))+COUNTIFS($F$2:F14,1,$D$2:D14,D14)-1) | L14: =IF(OR(D14="",NOT(G14="轿车")),"",1+SUMPRODUCT(($G$2:$G$1001="轿车")*($D$2:$D$1001>D14))+COUNTIFS($G$2:G14,"轿车",$D$2:D14,D14)-1) -> 66 | M14: =IF(OR(D14="",NOT(G14="MPV")),"",1+SUMPRODUCT(($G$2:$G$1001="MPV")*($D$2:$D$1001>D14))+COUNTIFS($G$2:G14,"MPV",$D$2:D14,D14)-1) | N14: =IF(OR(D14="",NOT(G14="SUV")),"",1+SUMPRODUCT(($G$2:$G$1001="SUV")*($D$2:$D$1001>D14))+COUNTIFS($G$2:G14,"SUV",$D$2:D14,D14)-1) | O14: =IF(OR(D14="",NOT(AND(F14=1,G14="轿车"))),"",1+SUMPRODUCT(($F$2:$F$1001=1)*($G$2:$G$1001="轿车")*($D$2:$D$1001>D14))+COUNTIFS($F$2:F14,1,$G$2:G14,"轿车",$D$2:D14,D14)-1) | P14: =IF(OR(D14="",NOT(AND(F14=1,G14="MPV"))),"",1+SUMPRODUCT(($F$2:$F$1001=1)*($G$2:$G$1001="MPV")*($D$2:$D$1001>D14))+COUNTIFS($F$2:F14,1,$G$2:G14,"MPV",$D$2:D14,D14)-1) | Q14: =IF(OR(D14="",NOT(AND(F14=1,G14="SUV"))),"",1+SUMPRODUCT(($F$2:$F$1001=1)*($G$2:$G$1001="SUV")*($D$2:$D$1001>D14))+COUNTIFS($F$2:F14,1,$G$2:G14,"SUV",$D$2:D14,D14)-1)
A15: =IFERROR(INDEX($H$2:$H$3000,MATCH(0,INDEX(COUNTIF($A$1:A14,$H$2:$H$3000)+($H$2:$H$3000=""),0,0),0)),"") -> AUDI♦A5 | B15: =IF(A15="","",LEFT(A15,FIND("♦",A15)-1)) -> AUDI | C15: =IF(A15="","",MID(A15,FIND("♦",A15)+1,999)) -> A5 | D15: =IF(A15="","",SUMIF($H$2:$H$3000,A15,$I$2:$I$3000)) -> 7 | E15: =IF(D15="","",_xlfn.RANK.EQ(D15,$D$2:$D$1001,0)+COUNTIF($D$2:D15,D15)-1) -> 155 | F15: =IF(B15="","",--(COUNTIF(CN_Brands!$A$2:$A$300,UPPER(B15))>0)) -> 0 | G15: =IF(A15="","",IFERROR(INDEX($J$2:$J$3000,MATCH(A15,$H$2:$H$3000,0)),"其他")) -> 轿车 | H15: =IF(AND('Data Export'!A15=前十整体车型排名!$B$2,'Data Export'!B15=前十整体车型排名!$B$3,'Data Export'!D15<>""),UPPER('Data Export'!C15)&"♦"&'Data Export'!D15,"") -> ASTON MARTIN♦VANTAGE | I15: =IF(H15="","",IFERROR(INDEX('Data Export'!G15:CZ15,1,MATCH(前十整体车型排名!$B$4,'Data Export'!$G$1:$CZ$1,0)),0)) -> 0 | J15: =IF(H15="","",IF(OR('Data Export'!F15="三厢轿车",'Data Export'!F15="掀背轿车",'Data Export'!F15="旅行车",'Data Export'!F15="微型车",'Data Export'!F15="硬顶跑车",'Data Export'!F15="敞蓬车",'Data Export'!F15="Targa"),"轿车",IF(OR('Data Export'!F15="小型MPV",'Data Export'!F15="客车"),"MPV",IF('Data Export'!F15="运动型多功能车","SUV","其他")))) -> 轿车 | K15: =IF(OR(D15="",NOT(F15=1)),"",1+SUMPRODUCT(($F$2:$F$1001=1)*($D$2:$D$1001>D15))+COUNTIFS($F$2:F15,1,$D$2:D15,D15)-1) | L15: =IF(OR(D15="",NOT(G15="轿车")),"",1+SUMPRODUCT(($G$2:$G$1001="轿车")*($D$2:$D$1001>D15))+COUNTIFS($G$2:G15,"轿车",$D$2:D15,D15)-1) -> 41 | M15: =IF(OR(D15="",NOT(G15="MPV")),"",1+SUMPRODUCT(($G$2:$G$1001="MPV")*($D$2:$D$1001>D15))+COUNTIFS($G$2:G15,"MPV",$D$2:D15,D15)-1) | N15: =IF(OR(D15="",NOT(G15="SUV")),"",1+SUMPRODUCT(($G$2:$G$1001="SUV")*($D$2:$D$1001>D15))+COUNTIFS($G$2:G15,"SUV",$D$2:D15,D15)-1) | O15: =IF(OR(D15="",NOT(AND(F15=1,G15="轿车"))),"",1+SUMPRODUCT(($F$2:$F$1001=1)*($G$2:$G$1001="轿车")*($D$2:$D$1001>D15))+COUNTIFS($F$2:F15,1,$G$2:G15,"轿车",$D$2:D15,D15)-1) | P15: =IF(OR(D15="",NOT(AND(F15=1,G15="MPV"))),"",1+SUMPRODUCT(($F$2:$F$1001=1)*($G$2:$G$1001="MPV")*($D$2:$D$1001>D15))+COUNTIFS($F$2:F15,1,$G$2:G15,"MPV",$D$2:D15,D15)-1) | Q15: =IF(OR(D15="",NOT(AND(F15=1,G15="SUV"))),"",1+SUMPRODUCT(($F$2:$F$1001=1)*($G$2:$G$1001="SUV")*($D$2:$D$1001>D15))+COUNTIFS($F$2:F15,1,$G$2:G15,"SUV",$D$2:D15,D15)-1)
A16: =IFERROR(INDEX($H$2:$H$3000,MATCH(0,INDEX(COUNTIF($A$1:A15,$H$2:$H$3000)+($H$2:$H$3000=""),0,0),0)),"") -> AUDI♦A6 | B16: =IF(A16="","",LEFT(A16,FIND("♦",A16)-1)) -> AUDI | C16: =IF(A16="","",MID(A16,FIND("♦",A16)+1,999)) -> A6 | D16: =IF(A16="","",SUMIF($H$2:$H$3000,A16,$I$2:$I$3000)) -> 0 | E16: =IF(D16="","",_xlfn.RANK.EQ(D16,$D$2:$D$1001,0)+COUNTIF($D$2:D16,D16)-1) -> 270 | F16: =IF(B16="","",--(COUNTIF(CN_Brands!$A$2:$A$300,UPPER(B16))>0)) -> 0 | G16: =IF(A16="","",IFERROR(INDEX($J$2:$J$3000,MATCH(A16,$H$2:$H$3000,0)),"其他")) -> 轿车 | H16: =IF(AND('Data Export'!A16=前十整体车型排名!$B$2,'Data Export'!B16=前十整体车型排名!$B$3,'Data Export'!D16<>""),UPPER('Data Export'!C16)&"♦"&'Data Export'!D16,"") -> ASTON MARTIN♦VANTAGE | I16: =IF(H16="","",IFERROR(INDEX('Data Export'!G16:CZ16,1,MATCH(前十整体车型排名!$B$4,'Data Export'!$G$1:$CZ$1,0)),0)) -> 0 | J16: =IF(H16="","",IF(OR('Data Export'!F16="三厢轿车",'Data Export'!F16="掀背轿车",'Data Export'!F16="旅行车",'Data Export'!F16="微型车",'Data Export'!F16="硬顶跑车",'Data Export'!F16="敞蓬车",'Data Export'!F16="Targa"),"轿车",IF(OR('Data Export'!F16="小型MPV",'Data Export'!F16="客车"),"MPV",IF('Data Export'!F16="运动型多功能车","SUV","其他")))) -> 轿车 | K16: =IF(OR(D16="",NOT(F16=1)),"",1+SUMPRODUCT(($F$2:$F$1001=1)*($D$2:$D$1001>D16))+COUNTIFS($F$2:F16,1,$D$2:D16,D16)-1) | L16: =IF(OR(D16="",NOT(G16="轿车")),"",1+SUMPRODUCT(($G$2:$G$1001="轿车")*($D$2:$D$1001>D16))+COUNTIFS($G$2:G16,"轿车",$D$2:D16,D16)-1) -> 87 | M16: =IF(OR(D16="",NOT(G16="MPV")),"",1+SUMPRODUCT(($G$2:$G$1001="MPV")*($D$2:$D$1001>D16))+COUNTIFS($G$2:G16,"MPV",$D$2:D16,D16)-1) | N16: =IF(OR(D16="",NOT(G16="SUV")),"",1+SUMPRODUCT(($G$2:$G$1001="SUV")*($D$2:$D$1001>D16))+COUNTIFS($G$2:G16,"SUV",$D$2:D16,D16)-1) | O16: =IF(OR(D16="",NOT(AND(F16=1,G16="轿车"))),"",1+SUMPRODUCT(($F$2:$F$1001=1)*($G$2:$G$1001="轿车")*($D$2:$D$1001>D16))+COUNTIFS($F$2:F16,1,$G$2:G16,"轿车",$D$2:D16,D16)-1) | P16: =IF(OR(D16="",NOT(AND(F16=1,G16="MPV"))),"",1+SUMPRODUCT(($F$2:$F$1001=1)*($G$2:$G$1001="MPV")*($D$2:$D$1001>D16))+COUNTIFS($F$2:F16,1,$G$2:G16,"MPV",$D$2:D16,D16)-1) | Q16: =IF(OR(D16="",NOT(AND(F16=1,G16="SUV"))),"",1+SUMPRODUCT(($F$2:$F$1001=1)*($G$2:$G$1001="SUV")*($D$2:$D$1001>D16))+COUNTIFS($F$2:F16,1,$G$2:G16,"SUV",$D$2:D16,D16)-1)
... A1001: =IFERROR(INDEX($H$2:$H$3000,MATCH(0,INDEX(COUNTIF($A$1:A1000,$H$2:$H$3000)+($H$2:$H$3000=""),0,0),0)),"") | B1001: =IF(A1001="","",LEFT(A1001,FIND("♦",A1001)-1)) | C1001: =IF(A1001="","",MID(A1001,FIND("♦",A1001)+1,999)) | D1001: =IF(A1001="","",SUMIF($H$2:$H$3000,A1001,$I$2:$I$3000)) | E1001: =IF(D1001="","",_xlfn.RANK.EQ(D1001,$D$2:$D$1001,0)+COUNTIF($D$2:D1001,D1001)-1) | F1001: =IF(B1001="","",--(COUNTIF(CN_Brands!$A$2:$A$300,UPPER(B1001))>0)) | G1001: =IF(A1001="","",IFERROR(INDEX($J$2:$J$3000,MATCH(A1001,$H$2:$H$3000,0)),"其他")) | H1001: =IF(AND('Data Export'!A1001=前十整体车型排名!$B$2,'Data Export'!B1001=前十整体车型排名!$B$3,'Data Export'!D1001<>""),UPPER('Data Export'!C1001)&"♦"&'Data Export'!D1001,"") | I1001: =IF(H1001="","",IFERROR(INDEX('Data Export'!G1001:CZ1001,1,MATCH(前十整体车型排名!$B$4,'Data Export'!$G$1:$CZ$1,0)),0)) | J1001: =IF(H1001="","",IF(OR('Data Export'!F1001="三厢轿车",'Data Export'!F1001="掀背轿车",'Data Export'!F1001="旅行车",'Data Export'!F1001="微型车",'Data Export'!F1001="硬顶跑车",'Data Export'!F1001="敞蓬车",'Data Export'!F1001="Targa"),"轿车",IF(OR('Data Export'!F1001="小型MPV",'Data Export'!F1001="客车"),"MPV",IF('Data Export'!F1001="运动型多功能车","SUV","其他")))) | K1001: =IF(OR(D1001="",NOT(F1001=1)),"",1+SUMPRODUCT(($F$2:$F$1001=1)*($D$2:$D$1001>D1001))+COUNTIFS($F$2:F1001,1,$D$2:D1001,D1001)-1) | L1001: =IF(OR(D1001="",NOT(G1001="轿车")),"",1+SUMPRODUCT(($G$2:$G$1001="轿车")*($D$2:$D$1001>D1001))+COUNTIFS($G$2:G1001,"轿车",$D$2:D1001,D1001)-1) | M1001: =IF(OR(D1001="",NOT(G1001="MPV")),"",1+SUMPRODUCT(($G$2:$G$1001="MPV")*($D$2:$D$1001>D1001))+COUNTIFS($G$2:G1001,"MPV",$D$2:D1001,D1001)-1) | N1001: =IF(OR(D1001="",NOT(G1001="SUV")),"",1+SUMPRODUCT(($G$2:$G$1001="SUV")*($D$2:$D$1001>D1001))+COUNTIFS($G$2:G1001,"SUV",$D$2:D1001,D1001)-1) | O1001: =IF(OR(D1001="",NOT(AND(F1001=1,G1001="轿车"))),"",1+SUMPRODUCT(($F$2:$F$1001=1)*($G$2:$G$1001="轿车")*($D$2:$D$1001>D1001))+COUNTIFS($F$2:F1001,1,$G$2:G1001,"轿车",$D$2:D1001,D1001)-1) | P1001: =IF(OR(D1001="",NOT(AND(F1001=1,G1001="MPV"))),"",1+SUMPRODUCT(($F$2:$F$1001=1)*($G$2:$G$1001="MPV")*($D$2:$D$1001>D1001))+COUNTIFS($F$2:F1001,1,$G$2:G1001,"MPV",$D$2:D1001,D1001)-1) | Q1001: =IF(OR(D1001="",NOT(AND(F1001=1,G1001="SUV"))),"",1+SUMPRODUCT(($F$2:$F$1001=1)*($G$2:$G$1001="SUV")*($D$2:$D$1001>D1001))+COUNTIFS($F$2:F1001,1,$G$2:G1001,"SUV",$D$2:D1001,D1001)-1)
H1002: =IF(AND('Data Export'!A1002=前十整体车型排名!$B$2,'Data Export'!B1002=前十整体车型排名!$B$3,'Data Export'!D1002<>""),UPPER('Data Export'!C1002)&"♦"&'Data Export'!D1002,"") | I1002: =IF(H1002="","",IFERROR(INDEX('Data Export'!G1002:CZ1002,1,MATCH(前十整体车型排名!$B$4,'Data Export'!$G$1:$CZ$1,0)),0)) | J1002: =IF(H1002="","",IF(OR('Data Export'!F1002="三厢轿车",'Data Export'!F1002="掀背轿车",'Data Export'!F1002="旅行车",'Data Export'!F1002="微型车",'Data Export'!F1002="硬顶跑车",'Data Export'!F1002="敞蓬车",'Data Export'!F1002="Targa"),"轿车",IF(OR('Data Export'!F1002="小型MPV",'Data Export'!F1002="客车"),"MPV",IF('Data Export'!F1002="运动型多功能车","SUV","其他"))))
H1003: =IF(AND('Data Export'!A1003=前十整体车型排名!$B$2,'Data Export'!B1003=前十整体车型排名!$B$3,'Data Export'!D1003<>""),UPPER('Data Export'!C1003)&"♦"&'Data Export'!D1003,"") | I1003: =IF(H1003="","",IFERROR(INDEX('Data Export'!G1003:CZ1003,1,MATCH(前十整体车型排名!$B$4,'Data Export'!$G$1:$CZ$1,0)),0)) | J1003: =IF(H1003="","",IF(OR('Data Export'!F1003="三厢轿车",'Data Export'!F1003="掀背轿车",'Data Export'!F1003="旅行车",'Data Export'!F1003="微型车",'Data Export'!F1003="硬顶跑车",'Data Export'!F1003="敞蓬车",'Data Export'!F1003="Targa"),"轿车",IF(OR('Data Export'!F1003="小型MPV",'Data Export'!F1003="客车"),"MPV",IF('Data Export'!F1003="运动型多功能车","SUV","其他"))))
H1004: =IF(AND('Data Export'!A1004=前十整体车型排名!$B$2,'Data Export'!B1004=前十整体车型排名!$B$3,'Data Export'!D1004<>""),UPPER('Data Export'!C1004)&"♦"&'Data Export'!D1004,"") | I1004: =IF(H1004="","",IFERROR(INDEX('Data Export'!G1004:CZ1004,1,MATCH(前十整体车型排名!$B$4,'Data Export'!$G$1:$CZ$1,0)),0)) | J1004: =IF(H1004="","",IF(OR('Data Export'!F1004="三厢轿车",'Data Export'!F1004="掀背轿车",'Data Export'!F1004="旅行车",'Data Export'!F1004="微型车",'Data Export'!F1004="硬顶跑车",'Data Export'!F1004="敞蓬车",'Data Export'!F1004="Targa"),"轿车",IF(OR('Data Export'!F1004="小型MPV",'Data Export'!F1004="客车"),"MPV",IF('Data Export'!F1004="运动型多功能车","SUV","其他"))))
H1005: =IF(AND('Data Export'!A1005=前十整体车型排名!$B$2,'Data Export'!B1005=前十整体车型排名!$B$3,'Data Export'!D1005<>""),UPPER('Data Export'!C1005)&"♦"&'Data Export'!D1005,"") | I1005: =IF(H1005="","",IFERROR(INDEX('Data Export'!G1005:CZ1005,1,MATCH(前十整体车型排名!$B$4,'Data Export'!$G$1:$CZ$1,0)),0)) | J1005: =IF(H1005="","",IF(OR('Data Export'!F1005="三厢轿车",'Data Export'!F1005="掀背轿车",'Data Export'!F1005="旅行车",'Data Export'!F1005="微型车",'Data Export'!F1005="硬顶跑车",'Data Export'!F1005="敞蓬车",'Data Export'!F1005="Targa"),"轿车",IF(OR('Data Export'!F1005="小型MPV",'Data Export'!F1005="客车"),"MPV",IF('Data Export'!F1005="运动型多功能车","SUV","其他"))))
H1006: =IF(AND('Data Export'!A1006=前十整体车型排名!$B$2,'Data Export'!B1006=前十整体车型排名!$B$3,'Data Export'!D1006<>""),UPPER('Data Export'!C1006)&"♦"&'Data Export'!D1006,"") | I1006: =IF(H1006="","",IFERROR(INDEX('Data Export'!G1006:CZ1006,1,MATCH(前十整体车型排名!$B$4,'Data Export'!$G$1:$CZ$1,0)),0)) | J1006: =IF(H1006="","",IF(OR('Data Export'!F1006="三厢轿车",'Data Export'!F1006="掀背轿车",'Data Export'!F1006="旅行车",'Data Export'!F1006="微型车",'Data Export'!F1006="硬顶跑车",'Data Export'!F1006="敞蓬车",'Data Export'!F1006="Targa"),"轿车",IF(OR('Data Export'!F1006="小型MPV",'Data Export'!F1006="客车"),"MPV",IF('Data Export'!F1006="运动型多功能车","SUV","其他"))))
H1007: =IF(AND('Data Export'!A1007=前十整体车型排名!$B$2,'Data Export'!B1007=前十整体车型排名!$B$3,'Data Export'!D1007<>""),UPPER('Data Export'!C1007)&"♦"&'Data Export'!D1007,"") | I1007: =IF(H1007="","",IFERROR(INDEX('Data Export'!G1007:CZ1007,1,MATCH(前十整体车型排名!$B$4,'Data Export'!$G$1:$CZ$1,0)),0)) | J1007: =IF(H1007="","",IF(OR('Data Export'!F1007="三厢轿车",'Data Export'!F1007="掀背轿车",'Data Export'!F1007="旅行车",'Data Export'!F1007="微型车",'Data Export'!F1007="硬顶跑车",'Data Export'!F1007="敞蓬车",'Data Export'!F1007="Targa"),"轿车",IF(OR('Data Export'!F1007="小型MPV",'Data Export'!F1007="客车"),"MPV",IF('Data Export'!F1007="运动型多功能车","SUV","其他"))))
H1008: =IF(AND('Data Export'!A1008=前十整体车型排名!$B$2,'Data Export'!B1008=前十整体车型排名!$B$3,'Data Export'!D1008<>""),UPPER('Data Export'!C1008)&"♦"&'Data Export'!D1008,"") | I1008: =IF(H1008="","",IFERROR(INDEX('Data Export'!G1008:CZ1008,1,MATCH(前十整体车型排名!$B$4,'Data Export'!$G$1:$CZ$1,0)),0)) | J1008: =IF(H1008="","",IF(OR('Data Export'!F1008="三厢轿车",'Data Export'!F1008="掀背轿车",'Data Export'!F1008="旅行车",'Data Export'!F1008="微型车",'Data Export'!F1008="硬顶跑车",'Data Export'!F1008="敞蓬车",'Data Export'!F1008="Targa"),"轿车",IF(OR('Data Export'!F1008="小型MPV",'Data Export'!F1008="客车"),"MPV",IF('Data Export'!F1008="运动型多功能车","SUV","其他"))))
H1009: =IF(AND('Data Export'!A1009=前十整体车型排名!$B$2,'Data Export'!B1009=前十整体车型排名!$B$3,'Data Export'!D1009<>""),UPPER('Data Export'!C1009)&"♦"&'Data Export'!D1009,"") | I1009: =IF(H1009="","",IFERROR(INDEX('Data Export'!G1009:CZ1009,1,MATCH(前十整体车型排名!$B$4,'Data Export'!$G$1:$CZ$1,0)),0)) | J1009: =IF(H1009="","",IF(OR('Data Export'!F1009="三厢轿车",'Data Export'!F1009="掀背轿车",'Data Export'!F1009="旅行车",'Data Export'!F1009="微型车",'Data Export'!F1009="硬顶跑车",'Data Export'!F1009="敞蓬车",'Data Export'!F1009="Targa"),"轿车",IF(OR('Data Export'!F1009="小型MPV",'Data Export'!F1009="客车"),"MPV",IF('Data Export'!F1009="运动型多功能车","SUV","其他"))))
H1010: =IF(AND('Data Export'!A1010=前十整体车型排名!$B$2,'Data Export'!B1010=前十整体车型排名!$B$3,'Data Export'!D1010<>""),UPPER('Data Export'!C1010)&"♦"&'Data Export'!D1010,"") | I1010: =IF(H1010="","",IFERROR(INDEX('Data Export'!G1010:CZ1010,1,MATCH(前十整体车型排名!$B$4,'Data Export'!$G$1:$CZ$1,0)),0)) | J1010: =IF(H1010="","",IF(OR('Data Export'!F1010="三厢轿车",'Data Export'!F1010="掀背轿车",'Data Export'!F1010="旅行车",'Data Export'!F1010="微型车",'Data Export'!F1010="硬顶跑车",'Data Export'!F1010="敞蓬车",'Data Export'!F1010="Targa"),"轿车",IF(OR('Data Export'!F1010="小型MPV",'Data Export'!F1010="客车"),"MPV",IF('Data Export'!F1010="运动型多功能车","SUV","其他"))))
H1011: =IF(AND('Data Export'!A1011=前十整体车型排名!$B$2,'Data Export'!B1011=前十整体车型排名!$B$3,'Data Export'!D1011<>""),UPPER('Data Export'!C1011)&"♦"&'Data Export'!D1011,"") | I1011: =IF(H1011="","",IFERROR(INDEX('Data Export'!G1011:CZ1011,1,MATCH(前十整体车型排名!$B$4,'Data Export'!$G$1:$CZ$1,0)),0)) | J1011: =IF(H1011="","",IF(OR('Data Export'!F1011="三厢轿车",'Data Export'!F1011="掀背轿车",'Data Export'!F1011="旅行车",'Data Export'!F1011="微型车",'Data Export'!F1011="硬顶跑车",'Data Export'!F1011="敞蓬车",'Data Export'!F1011="Targa"),"轿车",IF(OR('Data Export'!F1011="小型MPV",'Data Export'!F1011="客车"),"MPV",IF('Data Export'!F1011="运动型多功能车","SUV","其他"))))
H1012: =IF(AND('Data Export'!A1012=前十整体车型排名!$B$2,'Data Export'!B1012=前十整体车型排名!$B$3,'Data Export'!D1012<>""),UPPER('Data Export'!C1012)&"♦"&'Data Export'!D1012,"") | I1012: =IF(H1012="","",IFERROR(INDEX('Data Export'!G1012:CZ1012,1,MATCH(前十整体车型排名!$B$4,'Data Export'!$G$1:$CZ$1,0)),0)) | J1012: =IF(H1012="","",IF(OR('Data Export'!F1012="三厢轿车",'Data Export'!F1012="掀背轿车",'Data Export'!F1012="旅行车",'Data Export'!F1012="微型车",'Data Export'!F1012="硬顶跑车",'Data Export'!F1012="敞蓬车",'Data Export'!F1012="Targa"),"轿车",IF(OR('Data Export'!F1012="小型MPV",'Data Export'!F1012="客车"),"MPV",IF('Data Export'!F1012="运动型多功能车","SUV","其他"))))
H1013: =IF(AND('Data Export'!A1013=前十整体车型排名!$B$2,'Data Export'!B1013=前十整体车型排名!$B$3,'Data Export'!D1013<>""),UPPER('Data Export'!C1013)&"♦"&'Data Export'!D1013,"") | I1013: =IF(H1013="","",IFERROR(INDEX('Data Export'!G1013:CZ1013,1,MATCH(前十整体车型排名!$B$4,'Data Export'!$G$1:$CZ$1,0)),0)) | J1013: =IF(H1013="","",IF(OR('Data Export'!F1013="三厢轿车",'Data Export'!F1013="掀背轿车",'Data Export'!F1013="旅行车",'Data Export'!F1013="微型车",'Data Export'!F1013="硬顶跑车",'Data Export'!F1013="敞蓬车",'Data Export'!F1013="Targa"),"轿车",IF(OR('Data Export'!F1013="小型MPV",'Data Export'!F1013="客车"),"MPV",IF('Data Export'!F1013="运动型多功能车","SUV","其他"))))
... H3000: =IF(AND('Data Export'!A3000=前十整体车型排名!$B$2,'Data Export'!B3000=前十整体车型排名!$B$3,'Data Export'!D3000<>""),UPPER('Data Export'!C3000)&"♦"&'Data Export'!D3000,"") | I3000: =IF(H3000="","",IFERROR(INDEX('Data Export'!G3000:CZ3000,1,MATCH(前十整体车型排名!$B$4,'Data Export'!$G$1:$CZ$1,0)),0)) | J3000: =IF(H3000="","",IF(OR('Data Export'!F3000="三厢轿车",'Data Export'!F3000="掀背轿车",'Data Export'!F3000="旅行车",'Data Export'!F3000="微型车",'Data Export'!F3000="硬顶跑车",'Data Export'!F3000="敞蓬车",'Data Export'!F3000="Targa"),"轿车",IF(OR('Data Export'!F3000="小型MPV",'Data Export'!F3000="客车"),"MPV",IF('Data Export'!F3000="运动型多功能车","SUV","其他"))))

Sheet CN_Brands
A1: 英文品牌（匹配键） | B1: 品牌名称 | C1: Sales Group | D1: 派系 | E1: 自主或合资 | F1: 品牌级别 | G1: 品牌级别2 | I1: 中国品牌口径说明
A2: AION | B2: 埃安 | C2: GAC | D2: 0 | E2: 自主 | F2: 主流 | G2: 主流 | I2: 来源：副本IHS VLK（总） 20260821v1 - 副本.xlsx / 品牌对应。
A3: AISTALAND | B3: 启境 | C3: GAC | D3: 中国 | E3: 自主 | F3: 中高端 | G3: 中高端 | I3: 筛选条件：自主或合资＝自主；按 VS: Sales Brand 与 Data Export 品牌精确匹配（忽略大小写）。
A4: AITO | B4: 问界 | C4: Huawei | D4: 中国 | E4: 自主 | F4: 高端 | G4: 中高端 | I4: ="当前映射共 "&COUNTA(A2:A300)&" 个自主品牌" -> 当前映射共 203 个自主品牌
A5: ANKAI | B5: 安凯 | C5: Jianghuai | D5: 0 | E5: 自主 | F5: 商用/皮卡 | G5: 商用/皮卡
A6: ARCFOX | B6: 极狐 | C6: BAIC | D6: 中国 | E6: 自主 | F6: 高端 | G6: 中高端
A7: ASIA CAB | B7: 亚洲出租 | C7: Geely | D7: 0 | E7: 自主 | F7: 商用/皮卡 | G7: 商用/皮卡
A8: AVATR | B8: 阿维塔 | C8: Changan | D8: 0 | E8: 自主 | F8: 高端 | G8: 中高端
A9: BAIC | B9: 北汽 | C9: BAIC | D9: 中国 | E9: 自主 | F9: 主流 | G9: 主流
A10: BAOJUN | B10: 宝骏 | C10: SAIC-General Motors-Wuling | D10: 中国 | E10: 自主 | F10: 经济 | G10: 经济
A11: BAW | B11: 北汽制造 | C11: BAIC | D11: 中国 | E11: 自主 | F11: 商用/皮卡 | G11: 商用/皮卡
A12: BEIJING AUTO | B12: 北京汽车 | C12: BAIC | D12: 中国 | E12: 自主 | F12: 主流 | G12: 主流
A13: BESTUNE | B13: 奔腾 | C13: FAW | D13: 0 | E13: 自主 | F13: 主流 | G13: 主流
A14: BISU | B14: 比速 | C14: BAIC | D14: 0 | E14: 自主 | F14: 经济 | G14: 经济
A15: BJEV | B15: 北京新能源汽车 | C15: BAIC | D15: 中国 | E15: 自主 | F15: 主流 | G15: 主流
A16: BRILLIANCE | B16: 华晨/金杯 | C16: Brilliance Auto | D16: 中国 | E16: 自主 | F16: 主流 | G16: 主流
... A204: ZOTYE | B204: 众泰 | C204: Zotye | D204: 中国 | E204: 自主 | F204: 经济 | G204: 经济

Sheet V2_Calc
A1: 品牌 | B1: 最新月份销量 | C1: 中国品牌标记 | D1: 整体市场份额 | E1: 中国品牌排名 | G1: 品牌层汇总说明
A2: =IFERROR(INDEX(V1_Calc!$B$2:$B$1001,MATCH(0,INDEX(COUNTIF($A$1:A1,V1_Calc!$B$2:$B$1001)+(V1_Calc!$B$2:$B$1001=""),0,0),0)),"") -> AION | B2: =IF(A2="","",SUMIF(V1_Calc!$B$2:$B$1001,A2,V1_Calc!$D$2:$D$1001)) -> 1727 | C2: =IF(A2="","",--(COUNTIF(CN_Brands!$A$2:$A$300,UPPER(A2))>0)) -> 1 | D2: =IF(B2="","",IFERROR(B2/SUM($B$2:$B$201),0)) -> 0.037356695 | E2: =IF(OR(B2="",C2<>1),"",1+SUMPRODUCT(($C$2:$C$201=1)*($B$2:$B$201>B2))+COUNTIFS($C$2:C2,1,$B$2:B2,B2)-1) -> 6 | G2: A:E 全部为公式，用于“中国品牌市占率”报表。
A3: =IFERROR(INDEX(V1_Calc!$B$2:$B$1001,MATCH(0,INDEX(COUNTIF($A$1:A2,V1_Calc!$B$2:$B$1001)+(V1_Calc!$B$2:$B$1001=""),0,0),0)),"") -> ASTON MARTIN | B3: =IF(A3="","",SUMIF(V1_Calc!$B$2:$B$1001,A3,V1_Calc!$D$2:$D$1001)) -> 1 | C3: =IF(A3="","",--(COUNTIF(CN_Brands!$A$2:$A$300,UPPER(A3))>0)) -> 0 | D3: =IF(B3="","",IFERROR(B3/SUM($B$2:$B$201),0)) -> 2.1630976e-05 | E3: =IF(OR(B3="",C3<>1),"",1+SUMPRODUCT(($C$2:$C$201=1)*($B$2:$B$201>B3))+COUNTIFS($C$2:C3,1,$B$2:B3,B3)-1)
A4: =IFERROR(INDEX(V1_Calc!$B$2:$B$1001,MATCH(0,INDEX(COUNTIF($A$1:A3,V1_Calc!$B$2:$B$1001)+(V1_Calc!$B$2:$B$1001=""),0,0),0)),"") -> AUDI | B4: =IF(A4="","",SUMIF(V1_Calc!$B$2:$B$1001,A4,V1_Calc!$D$2:$D$1001)) -> 28 | C4: =IF(A4="","",--(COUNTIF(CN_Brands!$A$2:$A$300,UPPER(A4))>0)) -> 0 | D4: =IF(B4="","",IFERROR(B4/SUM($B$2:$B$201),0)) -> 0.00060566732 | E4: =IF(OR(B4="",C4<>1),"",1+SUMPRODUCT(($C$2:$C$201=1)*($B$2:$B$201>B4))+COUNTIFS($C$2:C4,1,$B$2:B4,B4)-1)
A5: =IFERROR(INDEX(V1_Calc!$B$2:$B$1001,MATCH(0,INDEX(COUNTIF($A$1:A4,V1_Calc!$B$2:$B$1001)+(V1_Calc!$B$2:$B$1001=""),0,0),0)),"") -> AVATR | B5: =IF(A5="","",SUMIF(V1_Calc!$B$2:$B$1001,A5,V1_Calc!$D$2:$D$1001)) -> 199 | C5: =IF(A5="","",--(COUNTIF(CN_Brands!$A$2:$A$300,UPPER(A5))>0)) -> 1 | D5: =IF(B5="","",IFERROR(B5/SUM($B$2:$B$201),0)) -> 0.0043045641 | E5: =IF(OR(B5="",C5<>1),"",1+SUMPRODUCT(($C$2:$C$201=1)*($B$2:$B$201>B5))+COUNTIFS($C$2:C5,1,$B$2:B5,B5)-1) -> 13
A6: =IFERROR(INDEX(V1_Calc!$B$2:$B$1001,MATCH(0,INDEX(COUNTIF($A$1:A5,V1_Calc!$B$2:$B$1001)+(V1_Calc!$B$2:$B$1001=""),0,0),0)),"") -> BENTLEY | B6: =IF(A6="","",SUMIF(V1_Calc!$B$2:$B$1001,A6,V1_Calc!$D$2:$D$1001)) -> 3 | C6: =IF(A6="","",--(COUNTIF(CN_Brands!$A$2:$A$300,UPPER(A6))>0)) -> 0 | D6: =IF(B6="","",IFERROR(B6/SUM($B$2:$B$201),0)) -> 6.4892927e-05 | E6: =IF(OR(B6="",C6<>1),"",1+SUMPRODUCT(($C$2:$C$201=1)*($B$2:$B$201>B6))+COUNTIFS($C$2:C6,1,$B$2:B6,B6)-1)
A7: =IFERROR(INDEX(V1_Calc!$B$2:$B$1001,MATCH(0,INDEX(COUNTIF($A$1:A6,V1_Calc!$B$2:$B$1001)+(V1_Calc!$B$2:$B$1001=""),0,0),0)),"") -> BMW | B7: =IF(A7="","",SUMIF(V1_Calc!$B$2:$B$1001,A7,V1_Calc!$D$2:$D$1001)) -> 870 | C7: =IF(A7="","",--(COUNTIF(CN_Brands!$A$2:$A$300,UPPER(A7))>0)) -> 0 | D7: =IF(B7="","",IFERROR(B7/SUM($B$2:$B$201),0)) -> 0.018818949 | E7: =IF(OR(B7="",C7<>1),"",1+SUMPRODUCT(($C$2:$C$201=1)*($B$2:$B$201>B7))+COUNTIFS($C$2:C7,1,$B$2:B7,B7)-1)
A8: =IFERROR(INDEX(V1_Calc!$B$2:$B$1001,MATCH(0,INDEX(COUNTIF($A$1:A7,V1_Calc!$B$2:$B$1001)+(V1_Calc!$B$2:$B$1001=""),0,0),0)),"") -> BYD | B8: =IF(A8="","",SUMIF(V1_Calc!$B$2:$B$1001,A8,V1_Calc!$D$2:$D$1001)) -> 3178 | C8: =IF(A8="","",--(COUNTIF(CN_Brands!$A$2:$A$300,UPPER(A8))>0)) -> 1 | D8: =IF(B8="","",IFERROR(B8/SUM($B$2:$B$201),0)) -> 0.06874324 | E8: =IF(OR(B8="",C8<>1),"",1+SUMPRODUCT(($C$2:$C$201=1)*($B$2:$B$201>B8))+COUNTIFS($C$2:C8,1,$B$2:B8,B8)-1) -> 1
A9: =IFERROR(INDEX(V1_Calc!$B$2:$B$1001,MATCH(0,INDEX(COUNTIF($A$1:A8,V1_Calc!$B$2:$B$1001)+(V1_Calc!$B$2:$B$1001=""),0,0),0)),"") -> CHANGAN | B9: =IF(A9="","",SUMIF(V1_Calc!$B$2:$B$1001,A9,V1_Calc!$D$2:$D$1001)) -> 513 | C9: =IF(A9="","",--(COUNTIF(CN_Brands!$A$2:$A$300,UPPER(A9))>0)) -> 1 | D9: =IF(B9="","",IFERROR(B9/SUM($B$2:$B$201),0)) -> 0.01109669 | E9: =IF(OR(B9="",C9<>1),"",1+SUMPRODUCT(($C$2:$C$201=1)*($B$2:$B$201>B9))+COUNTIFS($C$2:C9,1,$B$2:B9,B9)-1) -> 11
A10: =IFERROR(INDEX(V1_Calc!$B$2:$B$1001,MATCH(0,INDEX(COUNTIF($A$1:A9,V1_Calc!$B$2:$B$1001)+(V1_Calc!$B$2:$B$1001=""),0,0),0)),"") -> CHERY | B10: =IF(A10="","",SUMIF(V1_Calc!$B$2:$B$1001,A10,V1_Calc!$D$2:$D$1001)) -> 778 | C10: =IF(A10="","",--(COUNTIF(CN_Brands!$A$2:$A$300,UPPER(A10))>0)) -> 1 | D10: =IF(B10="","",IFERROR(B10/SUM($B$2:$B$201),0)) -> 0.016828899 | E10: =IF(OR(B10="",C10<>1),"",1+SUMPRODUCT(($C$2:$C$201=1)*($B$2:$B$201>B10))+COUNTIFS($C$2:C10,1,$B$2:B10,B10)-1) -> 8
A11: =IFERROR(INDEX(V1_Calc!$B$2:$B$1001,MATCH(0,INDEX(COUNTIF($A$1:A10,V1_Calc!$B$2:$B$1001)+(V1_Calc!$B$2:$B$1001=""),0,0),0)),"") -> CHEVROLET | B11: =IF(A11="","",SUMIF(V1_Calc!$B$2:$B$1001,A11,V1_Calc!$D$2:$D$1001)) -> 1 | C11: =IF(A11="","",--(COUNTIF(CN_Brands!$A$2:$A$300,UPPER(A11))>0)) -> 0 | D11: =IF(B11="","",IFERROR(B11/SUM($B$2:$B$201),0)) -> 2.1630976e-05 | E11: =IF(OR(B11="",C11<>1),"",1+SUMPRODUCT(($C$2:$C$201=1)*($B$2:$B$201>B11))+COUNTIFS($C$2:C11,1,$B$2:B11,B11)-1)
A12: =IFERROR(INDEX(V1_Calc!$B$2:$B$1001,MATCH(0,INDEX(COUNTIF($A$1:A11,V1_Calc!$B$2:$B$1001)+(V1_Calc!$B$2:$B$1001=""),0,0),0)),"") -> DAIHATSU | B12: =IF(A12="","",SUMIF(V1_Calc!$B$2:$B$1001,A12,V1_Calc!$D$2:$D$1001)) -> 1 | C12: =IF(A12="","",--(COUNTIF(CN_Brands!$A$2:$A$300,UPPER(A12))>0)) -> 0 | D12: =IF(B12="","",IFERROR(B12/SUM($B$2:$B$201),0)) -> 2.1630976e-05 | E12: =IF(OR(B12="",C12<>1),"",1+SUMPRODUCT(($C$2:$C$201=1)*($B$2:$B$201>B12))+COUNTIFS($C$2:C12,1,$B$2:B12,B12)-1)
A13: =IFERROR(INDEX(V1_Calc!$B$2:$B$1001,MATCH(0,INDEX(COUNTIF($A$1:A12,V1_Calc!$B$2:$B$1001)+(V1_Calc!$B$2:$B$1001=""),0,0),0)),"") -> DAYUN | B13: =IF(A13="","",SUMIF(V1_Calc!$B$2:$B$1001,A13,V1_Calc!$D$2:$D$1001)) -> 0 | C13: =IF(A13="","",--(COUNTIF(CN_Brands!$A$2:$A$300,UPPER(A13))>0)) -> 1 | D13: =IF(B13="","",IFERROR(B13/SUM($B$2:$B$201),0)) -> 0 | E13: =IF(OR(B13="",C13<>1),"",1+SUMPRODUCT(($C$2:$C$201=1)*($B$2:$B$201>B13))+COUNTIFS($C$2:C13,1,$B$2:B13,B13)-1) -> 24
A14: =IFERROR(INDEX(V1_Calc!$B$2:$B$1001,MATCH(0,INDEX(COUNTIF($A$1:A13,V1_Calc!$B$2:$B$1001)+(V1_Calc!$B$2:$B$1001=""),0,0),0)),"") -> DEEPAL | B14: =IF(A14="","",SUMIF(V1_Calc!$B$2:$B$1001,A14,V1_Calc!$D$2:$D$1001)) -> 1572 | C14: =IF(A14="","",--(COUNTIF(CN_Brands!$A$2:$A$300,UPPER(A14))>0)) -> 1 | D14: =IF(B14="","",IFERROR(B14/SUM($B$2:$B$201),0)) -> 0.034003894 | E14: =IF(OR(B14="",C14<>1),"",1+SUMPRODUCT(($C$2:$C$201=1)*($B$2:$B$201>B14))+COUNTIFS($C$2:C14,1,$B$2:B14,B14)-1) -> 7
